Workbook

Sheet base vs fixed vs dynamic
M1: Inference
D2: Power | H2: HW Utilization | M2: Model1 | O2: Model2 | Q2: Model3 | S2: FoM_1 Max | T2: Timing Report (ns)
C3: Engine | D3: Total_Power(W) | E3: Dynamic_Power(W) | F3: Static_Power(W) | G3: SA_Power(W) | H3: LUT_SA | I3: FF_SA | J3: BRAM_TOP | K3: LUT_TOP | L3: FF_TOP | M3: Accuracy(%) | N3: Fidelity(%) | O3: Accuracy(%) | P3: Fidelity(%) | Q3: Accuracy(%) | R3: Fidelity(%) | S3: =MAX(S4:S273) -> 24970.315 | T3: WNS | U3: WHS | V3: WPWS
C4: Baseline | D4: 0.264 | E4: 0.155 | F4: 0.109 | G4: 0.076 | H4: 5971 | I4: 4621 | J4: 72 | K4: 6960 | L4: 6643 | M4: 76 | N4: 100 | O4: 92 | P4: 100 | Q4: 52 | R4: 100
C5: Fixed-7 | D5: 0.249 | E5: 0.14 | F5: 0.109 | G5: 0.062 | H5: 5979 | I5: 4557 | J5: 72 | K5: 6972 | L5: 6643 | M5: 89 | N5: 74 | O5: 86 | P5: 87 | Q5: 49 | R5: 87 | S5: =(M5*N5*O5*P5*Q5*R5)/(H5*I5*J5*(E5*G5)) -> 12336.585
C6: Fixed-6 | D6: 0.31 | E6: 0.2 | F6: 0.109 | G6: 0.053 | H6: 4692 | I6: 4253 | J6: 64 | K6: 5526 | L6: 6225 | M6: 83.5 | N6: 75.5 | O6: 84.5 | P6: 86.5 | Q6: 49 | R6: 84 | S6: =(M6*N6*O6*P6*Q6*R6)/(H6*I6*J6*(E6*G6)) -> 14010.137
C7: Fixed_5 | D7: 0.28 | E7: 0.172 | F7: 0.108 | G7: 0.041 | H7: 3316 | I7: 3949 | J7: 56 | K7: 4118 | L7: 5903 | M7: 60 | N7: 56 | O7: 81 | P7: 82.5 | Q7: 49 | R7: 83 | S7: =(M7*N7*O7*P7*Q7*R7)/(H7*I7*J7*(E7*G7)) -> 17658.363
C8: Fixed-4 | D8: 0.255 | E8: 0.148 | F8: 0.108 | G8: 0.032 | H8: 2732 | I8: 3645 | J8: 48 | K8: 3539 | L8: 5581 | M8: 32 | N8: 31 | O8: 65 | P8: 66 | Q8: 48.5 | R8: 77 | S8: =(M8*N8*O8*P8*Q8*R8)/(H8*I8*J8*(E8*G8)) -> 7020.536
C9: M5 | D9: 0.253 | E9: 0.145 | F9: 0.109 | G9: 0.067 | H9: 5299 | I9: 4493 | J9: 72 | K9: 6292 | L9: 6515 | M9: 76 | N9: 98 | O9: 91 | P9: 98 | Q9: 52 | R9: 98.5 | S9: =(M9*N9*O9*P9*Q9*R9)/(H9*I9*J9*(E9*G9)) -> 20428.716 | T9: 1.656 | U9: 0.067 | V9: 4.02
C10: M4 | D10: 0.251 | E10: 0.143 | F10: 0.109 | G10: 0.065 | H10: 5612 | I10: 4429 | J10: 72 | K10: 6623 | L10: 6451 | M10: 75.5 | N10: 96.5 | O10: 90.5 | P10: 97 | Q10: 51 | R10: 96 | S10: =(M10*N10*O10*P10*Q10*R10)/(H10*I10*J10*(E10*G10)) -> 18824.817 | T10: 1.703 | U10: 0.081 | V10: 4.02
C11: M3 | D11: 0.31 | E11: 0.201 | F11: 0.109 | G11: 0.054 | H11: 4604 | I11: 4125 | J11: 64 | K11: 5425 | L11: 6097 | M11: 74.5 | N11: 92 | O11: 89.5 | P11: 94 | Q11: 50.5 | R11: 93.5 | S11: =(M11*N11*O11*P11*Q11*R11)/(H11*I11*J11*(E11*G11)) -> 20638.062 | T11: 1.527 | U11: 0.08 | V11: 4.02
C12: M2 | D12: 0.288 | E12: 0.18 | F12: 0.108 | G12: 0.048 | H12: 4542 | I12: 3821 | J12: 56 | K12: 5350 | L12: 5775 | M12: 72 | N12: 86 | O12: 87.5 | P12: 90 | Q12: 50 | R12: 86 | S12: =(M12*N12*O12*P12*Q12*R12)/(H12*I12*J12*(E12*G12)) -> 24970.315 | T12: 1.653 | U12: 0.079 | V12: 4.02
C13: M1 | D13: 0.263 | E13: 0.155 | F13: 0.108 | G13: 0.038 | H13: 3648 | I13: 3453 | J13: 48 | K13: 4447 | L13: 5389 | M13: 67 | N13: 71 | O13: 65.5 | P13: 66 | Q13: 48 | R13: 73.5 | S13: =(M13*N13*O13*P13*Q13*R13)/(H13*I13*J13*(E13*G13)) -> 20372.251 | T13: 2.051 | U13: 0.079 | V13: 4.02
E20: Engines | F20: PWR_SA(W) | G20: LUT_SA | H20: FF_SA | I20: Total BRAM | J20: Error Avg(%) | K20: Error Var(‰)
E21: Baseline | F21: 0.076 | G21: 5971 | H21: 4621 | I21: 72 | J21: 0 | K21: 0
E22: Fixed-7 | F22: 0.062 | G22: 5979 | H22: 4557 | I22: 72 | J22: 4.821 | K22: 18.97 | M22: Engine | N22: Accuracy, Fidelity (%) | O22: Engine | P22: Fidelity(%) | Q22: Engine | R22: Fidelity(%)
E23: Fixed-6 | F23: 0.053 | G23: 4692 | H23: 4253 | I23: 64 | J23: 8.157 | K23: 33.55 | L23: Baseline | M23: Model1 | N23: 76 | O23: Fixed-7 | P23: 87 | Q23: Fixed-7 | R23: 87
E24: Fixed_5 | F24: 0.041 | G24: 3316 | H24: 3949 | I24: 56 | J24: 14.22 | K24: 61.02 | M24: Model2 | N24: 92 | O24: Fixed-6 | P24: 86.5 | Q24: Fixed-6 | R24: 84
E25: Fixed-4 | F25: 0.032 | G25: 2732 | H25: 3645 | I25: 48 | J25: 17.31 | K25: 103.6 | M25: Model3 | N25: 52 | O25: Fixed_5 | P25: 82.5 | Q25: Fixed_5 | R25: 83
E26: M5 | F26: 0.067 | G26: 5299 | H26: 4493 | I26: 72 | J26: 1.424 | K26: 0.162 | L26: Fixed-7 | M26: Model1 | N26: 74 | O26: Fixed-4 | P26: 66 | Q26: Fixed-4 | R26: 77
E27: M4 | F27: 0.065 | G27: 5612 | H27: 4429 | I27: 72 | J27: 2.957 | K27: 0.546 | M27: Model2 | N27: 87 | O27: M5 | P27: 98 | Q27: M5 | R27: 98.5
E28: M3 | F28: 0.054 | G28: 4604 | H28: 4125 | I28: 64 | J28: 5.88 | K28: 1.973 | M28: Model3 | N28: 87 | O28: M4 | P28: 97 | Q28: M4 | R28: 96
E29: M2 | F29: 0.048 | G29: 4542 | H29: 3821 | I29: 56 | J29: 9.365 | K29: 4.352 | L29: Fixed-6 | M29: Model1 | N29: 75.5 | O29: M3 | P29: 94 | Q29: M3 | R29: 93.5
E30: M1 | F30: 0.038 | G30: 3648 | H30: 3453 | I30: 48 | J30: 17.31 | K30: 11.52 | M30: Model2 | N30: 86.5 | O30: M2 | P30: 90 | Q30: M2 | R30: 86
M31: Model3 | N31: 84 | O31: M1 | P31: 66 | Q31: M1 | R31: 73.5
L32: Fixed_5 | M32: Model1 | N32: 56
M33: Model2 | N33: 82.5
M34: Model3 | N34: 83
L35: Fixed-4 | M35: Model1 | N35: 31
M36: Model2 | N36: 66
M37: Model3 | N37: 77
L38: M5 | M38: Model1 | N38: 98
M39: Model2 | N39: 98
M40: Model3 | N40: 98.5
L41: M4 | M41: Model1 | N41: 96.5
M42: Model2 | N42: 97
M43: Model3 | N43: 96.5
L44: M3 | M44: Model1 | N44: 92
M45: Model2 | N45: 94
M46: Model3 | N46: 93.5
...

Sheet dynamic scaling metrics
N1: Inference | X1: =MIN(X4:X273) -> 0.016 | Y1: =MIN(Y4:Y273) -> 0.036 | Z1: =MIN(Z4:Z273) -> 0.017 | AA1: =MIN(AA4:AA273) -> 0.015 | AB1: =MIN(AB4:AB273) -> 0.017 | AF1: =MAX(AF9,AF15,AF21,AF27,AF33,AF39,AF45,AF51,AF57,AF63,AF69,AF75,AF81,AF87,AF93,AF99,AF105,AF111,AF117,AF123,AF129,AF135,AF141,AF147,AF153,AF159,AF165,AF171,AF177,AF183,AF189,AF195,AF201,AF207,AF213,AF219,AF225,AF231,AF237,AF243,AF249,AF255,AF261,AF267,AF273) -> 1894.5009 | AG1: =MAX(AG9,AG15,AG21,AG27,AG33,AG39,AG45,AG51,AG57,AG63,AG69,AG75,AG81,AG87,AG93,AG99,AG105,AG111,AG117,AG123,AG129,AG135,AG141,AG147,AG153,AG159,AG165,AG171,AG177,AG183,AG189,AG195,AG201,AG207,AG213,AG219,AG225,AG231,AG237,AG243,AG249,AG255,AG261,AG267,AG273) -> 1977.3352 | AH1: =MAX(AH9,AH15,AH21,AH27,AH33,AH39,AH45,AH51,AH57,AH63,AH69,AH75,AH81,AH87,AH93,AH99,AH105,AH111,AH117,AH123,AH129,AH135,AH141,AH147,AH153,AH159,AH165,AH171,AH177,AH183,AH189,AH195,AH201,AH207,AH213,AH219,AH225,AH231,AH237,AH243,AH249,AH255,AH261,AH267,AH273) -> 2088.3324 | AI1: =MAX(AI9,AI15,AI21,AI27,AI33,AI39,AI45,AI51,AI57,AI63,AI69,AI75,AI81,AI87,AI93,AI99,AI105,AI111,AI117,AI123,AI129,AI135,AI141,AI147,AI153,AI159,AI165,AI171,AI177,AI183,AI189,AI195,AI201,AI207,AI213,AI219,AI225,AI231,AI237,AI243,AI249,AI255,AI261,AI267,AI273) -> 2574.8505 | AJ1: =MAX(AJ9,AJ15,AJ21,AJ27,AJ33,AJ39,AJ45,AJ51,AJ57,AJ63,AJ69,AJ75,AJ81,AJ87,AJ93,AJ99,AJ105,AJ111,AJ117,AJ123,AJ129,AJ135,AJ141,AJ147,AJ153,AJ159,AJ165,AJ171,AJ177,AJ183,AJ189,AJ195,AJ201,AJ207,AJ213,AJ219,AJ225,AJ231,AJ237,AJ243,AJ249,AJ255,AJ261,AJ267,AJ273) -> 2488.9732 | AK1: =MAX(AK9,AK15,AK21,AK27,AK33,AK39,AK45,AK51,AK57,AK63,AK69,AK75,AK81,AK87,AK93,AK99,AK105,AK111,AK117,AK123,AK129,AK135,AK141,AK147,AK153,AK159,AK165,AK171,AK177,AK183,AK189,AK195,AK201,AK207,AK213,AK219,AK225,AK231,AK237,AK243,AK249,AK255,AK261,AK267,AK273) -> 2968.8262 | AL1: =MAX(AL9,AL15,AL21,AL27,AL33,AL39,AL45,AL51,AL57,AL63,AL69,AL75,AL81,AL87,AL93,AL99,AL105,AL111,AL117,AL123,AL129,AL135,AL141,AL147,AL153,AL159,AL165,AL171,AL177,AL183,AL189,AL195,AL201,AL207,AL213,AL219,AL225,AL231,AL237,AL243,AL249,AL255,AL261,AL267,AL273) -> 3256.7393 | AM1: =MAX(AM9,AM15,AM21,AM27,AM33,AM39,AM45,AM51,AM57,AM63,AM69,AM75,AM81,AM87,AM93,AM99,AM105,AM111,AM117,AM123,AM129,AM135,AM141,AM147,AM153,AM159,AM165,AM171,AM177,AM183,AM189,AM195,AM201,AM207,AM213,AM219,AM225,AM231,AM237,AM243,AM249,AM255,AM261,AM267,AM273) -> 3956.193 | ... CQ1: =MAX(CQ9,CQ15,CQ21,CQ27,CQ33,CQ39,CQ45,CQ51,CQ57,CQ63,CQ69,CQ75,CQ81,CQ87,CQ93,CQ99,CQ105,CQ111,CQ117,CQ123,CQ129,CQ135,CQ141,CQ147,CQ153,CQ159,CQ165,CQ171,CQ177,CQ183,CQ189,CQ195,CQ201,CQ207,CQ213,CQ219,CQ225,CQ231,CQ237,CQ243,CQ249,CQ255,CQ261,CQ267,CQ273) -> 4517.7081 | CS1: =MAX(CS9,CS15,CS21,CS27,CS33,CS39,CS45,CS51,CS57,CS63,CS69,CS75,CS81,CS87,CS93,CS99,CS105,CS111,CS117,CS123,CS129,CS135,CS141,CS147,CS153,CS159,CS165,CS171,CS177,CS183,CS189,CS195,CS201,CS207,CS213,CS219,CS225,CS231,CS237,CS243,CS249,CS255,CS261,CS267,CS273) -> 100
E2: Power | I2: HW Utilization | N2: Model1 | P2: Model2 | R2: Model3 | T2: FoM_2 Max | U2: Timing Report (ns) | X2: Bitband Region_SA | AC2: =MIN(AC4:AC273) -> 3835.4484 | AD2: Fidelity/Sparsity | AE2: Weight | AF2: 0 | AG2: 0 | AH2: 0 | AI2: 0 | AJ2: 0 | AK2: 0 | AL2: 0 | AM2: 0 | AN2: 0.125 | AO2: 0.125 | AP2: 0.125 | AQ2: 0.125 | AR2: 0.125 | AS2: 0.125 | AT2: 0.125 | AU2: 0.125 | AV2: =AN2+0.125 -> 0.25 | AW2: =AO2+0.125 -> 0.25 | AX2: =AP2+0.125 -> 0.25 | AY2: =AQ2+0.125 -> 0.25 | AZ2: =AR2+0.125 -> 0.25 | BA2: =AS2+0.125 -> 0.25 | BB2: =AT2+0.125 -> 0.25 | BC2: =AU2+0.125 -> 0.25 | ... CQ2: =CI2+0.125 -> 0.875 | CR2: Weight | CS2: 0 | CT2: 0 | CU2: 0 | CV2: 0 | CW2: 0 | CX2: 0 | CY2: 0 | CZ2: 0 | DA2: 0.125 | DB2: 0.125 | DC2: 0.125 | DD2: 0.125 | DE2: 0.125 | DF2: 0.125 | DG2: 0.125 | DH2: 0.125 | DI2: =DA2+0.125 -> 0.25 | DJ2: =DB2+0.125 -> 0.25 | DK2: =DC2+0.125 -> 0.25 | DL2: =DD2+0.125 -> 0.25 | DM2: =DE2+0.125 -> 0.25 | DN2: =DF2+0.125 -> 0.25 | DO2: =DG2+0.125 -> 0.25 | DP2: =DH2+0.125 -> 0.25 | ... FD2: =EV2+0.125 -> 0.875
C3: Engine | D3: Testbench | E3: Total_Power(W) | F3: Dynamic_Power(W) | G3: Static_Power(W) | H3: SA_Power(W) | I3: LUT_SA | J3: FF_SA | K3: BRAM_TOP | L3: LUT_TOP | M3: FF_TOP | N3: Accuracy(%) | O3: Fidelity(%) | P3: Accuracy(%) | Q3: Fidelity(%) | R3: Accuracy(%) | S3: Fidelity(%) | T3: =MAX(T4:T273) -> 8255.9961 | U3: WNS | V3: WHS | W3: WPWS | X3: tb_nzzr | Y3: tb_swnz | Z3: tb_swzr | AA3: tb_zrnz | AB3: tb_zrzr | AC3: Fidelity/HW | AE3: Input | AF3: 0 | AG3: 0.125 | AH3: 0.25 | AI3: 0.375 | AJ3: 0.5 | AK3: 0.625 | AL3: 0.75 | AM3: 0.875 | AN3: =AF3 -> 0 | AO3: =AG3 -> 0.125 | AP3: =AH3 -> 0.25 | AQ3: =AI3 -> 0.375 | AR3: =AJ3 -> 0.5 | AS3: =AK3 -> 0.625 | AT3: =AL3 -> 0.75 | AU3: =AM3 -> 0.875 | ... CQ3: =CI3 -> 0.875 | CR3: Input | CS3: 0 | CT3: 0.125 | CU3: 0.25 | CV3: 0.375 | CW3: 0.5 | CX3: 0.625 | CY3: 0.75 | CZ3: 0.875 | DA3: =CS3 -> 0 | DB3: =CT3 -> 0.125 | DC3: =CU3 -> 0.25 | DD3: =CV3 -> 0.375 | DE3: =CW3 -> 0.5 | DF3: =CX3 -> 0.625 | DG3: =CY3 -> 0.75 | DH3: =CZ3 -> 0.875 | ... FD3: =EV3 -> 0.875
C4: M1no1 | D4: tb_nznz | E4: 0.263 | F4: 0.155 | G4: 0.108 | H4: 0.038 | I4: 3648 | J4: 3453 | K4: 48 | L4: 4447 | M4: 5389 | N4: 67 | O4: 71 | P4: 65.5 | Q4: 66 | R4: 48 | S4: 73.5 | T4: 0 | U4: 2.051 | V4: 0.079 | W4: 4.02 | X4: =H5 -> 0.021 | Y4: =H6 -> 0.048 | Z4: =H7 -> 0.027 | AA4: =H8 -> 0.016 | AB4: =H9 -> 0.027 | AC4: =1000000*((O4*Q4*S4)^(1/3))/(I4+0.5*J4+240*K4) -> 4149.0742 | AE4: NZ rate | AF4: 1 | AG4: 0.815 | AH4: 0.645 | AI4: 0.395 | AJ4: 0.36 | AK4: 0.245 | AL4: 0.145 | AM4: 0.065 | AN4: 1 | AO4: 0.815 | AP4: 0.645 | AQ4: 0.395 | AR4: 0.36 | AS4: 0.245 | AT4: 0.145 | AU4: 0.065 | AV4: 1 | AW4: 0.815 | AX4: 0.645 | AY4: 0.395 | AZ4: 0.36 | BA4: 0.245 | BB4: 0.145 | BC4: 0.065 | BD4: 1 | BE4: 0.815 | BF4: 0.645 | BG4: 0.395 | BH4: 0.36 | BI4: 0.245 | BJ4: 0.145 | BK4: 0.065 | BL4: 1 | BM4: 0.815 | BN4: 0.645 | BO4: 0.395 | BP4: 0.36 | BQ4: 0.245 | BR4: 0.145 | BS4: 0.065 | BT4: 1 | BU4: 0.815 | BV4: 0.645 | BW4: 0.395 | BX4: 0.36 | BY4: 0.245 | BZ4: 0.145 | CA4: 0.065 | CB4: 1 | CC4: 0.815 | CD4: 0.645 | CE4: 0.395 | CF4: 0.36 | CG4: 0.245 | CH4: 0.145 | CI4: 0.065 | CJ4: 1 | CK4: 0.815 | CL4: 0.645 | CM4: 0.395 | CN4: 0.36 | CO4: 0.245 | CP4: 0.145 | CQ4: 0.065
C5: M1no1 | D5: tb_nzzr | E5: 0.239 | F5: 0.131 | G5: 0.107 | H5: 0.021 | I5: 3648 | J5: 3453 | K5: 48 | L5: 4447 | M5: 5389 | N5: 67 | O5: 71 | P5: 65.5 | Q5: 66 | R5: 48 | S5: 73.5 | T5: 0 | U5: 2.051 | V5: 0.079 | W5: 4.02 | X5: =H5 -> 0.021 | Y5: =H6 -> 0.048 | Z5: =H7 -> 0.027 | AA5: =H8 -> 0.016 | AB5: =H9 -> 0.027 | AC5: =1000000*(O5*Q5*S5)^(1/3)/(I5+0.5*J5+240*K5) -> 4149.0742
C6: M1no1 | D6: tb_swnz | E6: 0.273 | F6: 0.165 | G6: 0.108 | H6: 0.048 | I6: 3648 | J6: 3453 | K6: 48 | L6: 4447 | M6: 5389 | N6: 67 | O6: 71 | P6: 65.5 | Q6: 66 | R6: 48 | S6: 73.5 | T6: 0 | U6: 2.051 | V6: 0.079 | W6: 4.02 | X6: =H5 -> 0.021 | Y6: =H6 -> 0.048 | Z6: =H7 -> 0.027 | AA6: =H8 -> 0.016 | AB6: =H9 -> 0.027 | AC6: =1000000*(O6*Q6*S6)^(1/3)/(I6+0.5*J6+240*K6) -> 4149.0742 | AE6: SW rate | AF6: 0 | AG6: 0.12 | AH6: 0.21 | AI6: 0.26 | AJ6: 0.28 | AK6: 0.26 | AL6: 0.21 | AM6: 0.12 | AN6: 0 | AO6: 0.12 | AP6: 0.21 | AQ6: 0.26 | AR6: 0.28 | AS6: 0.26 | AT6: 0.21 | AU6: 0.12 | AV6: 0 | AW6: 0.12 | AX6: 0.21 | AY6: 0.26 | AZ6: 0.28 | BA6: 0.26 | BB6: 0.21 | BC6: 0.12 | BD6: 0 | BE6: 0.12 | BF6: 0.21 | BG6: 0.26 | BH6: 0.28 | BI6: 0.26 | BJ6: 0.21 | BK6: 0.12 | BL6: 0 | BM6: 0.12 | BN6: 0.21 | BO6: 0.26 | BP6: 0.28 | BQ6: 0.26 | BR6: 0.21 | BS6: 0.12 | BT6: 0 | BU6: 0.12 | BV6: 0.21 | BW6: 0.26 | BX6: 0.28 | BY6: 0.26 | BZ6: 0.21 | CA6: 0.12 | CB6: 0 | CC6: 0.12 | CD6: 0.21 | CE6: 0.26 | CF6: 0.28 | CG6: 0.26 | CH6: 0.21 | CI6: 0.12 | CJ6: 0 | CK6: 0.12 | CL6: 0.21 | CM6: 0.26 | CN6: 0.28 | CO6: 0.26 | CP6: 0.21 | CQ6: 0.12
C7: M1no1 | D7: tb_swzr | E7: 0.245 | F7: 0.138 | G7: 0.107 | H7: 0.027 | I7: 3648 | J7: 3453 | K7: 48 | L7: 4447 | M7: 5389 | N7: 67 | O7: 71 | P7: 65.5 | Q7: 66 | R7: 48 | S7: 73.5 | T7: 0 | U7: 2.051 | V7: 0.079 | W7: 4.02 | X7: =H5 -> 0.021 | Y7: =H6 -> 0.048 | Z7: =H7 -> 0.027 | AA7: =H8 -> 0.016 | AB7: =H9 -> 0.027 | AC7: =1000000*(O7*Q7*S7)^(1/3)/(I7+0.5*J7+240*K7) -> 4149.0742
C8: M1no1 | D8: tb_zrnz | E8: 0.233 | F8: 0.126 | G8: 0.107 | H8: 0.016 | I8: 3648 | J8: 3453 | K8: 48 | L8: 4447 | M8: 5389 | N8: 67 | O8: 71 | P8: 65.5 | Q8: 66 | R8: 48 | S8: 73.5 | T8: 0 | U8: 2.051 | V8: 0.079 | W8: 4.02 | X8: =H5 -> 0.021 | Y8: =H6 -> 0.048 | Z8: =H7 -> 0.027 | AA8: =H8 -> 0.016 | AB8: =H9 -> 0.027 | AC8: =1000000*(O8*Q8*S8)^(1/3)/(I8+0.5*J8+240*K8) -> 4149.0742 | AE8: ZR rate | AF8: 0 | AG8: 0.065 | AH8: 0.145 | AI8: 0.245 | AJ8: 0.36 | AK8: 0.395 | AL8: 0.645 | AM8: 0.815 | AN8: 0 | AO8: 0.065 | AP8: 0.145 | AQ8: 0.245 | AR8: 0.36 | AS8: 0.395 | AT8: 0.645 | AU8: 0.815 | AV8: 0 | AW8: 0.065 | AX8: 0.145 | AY8: 0.245 | AZ8: 0.36 | BA8: 0.395 | BB8: 0.645 | BC8: 0.815 | BD8: 0 | BE8: 0.065 | BF8: 0.145 | BG8: 0.245 | BH8: 0.36 | BI8: 0.395 | BJ8: 0.645 | BK8: 0.815 | BL8: 0 | BM8: 0.065 | BN8: 0.145 | BO8: 0.245 | BP8: 0.36 | BQ8: 0.395 | BR8: 0.645 | BS8: 0.815 | BT8: 0 | BU8: 0.065 | BV8: 0.145 | BW8: 0.245 | BX8: 0.36 | BY8: 0.395 | BZ8: 0.645 | CA8: 0.815 | CB8: 0 | CC8: 0.065 | CD8: 0.145 | CE8: 0.245 | CF8: 0.36 | CG8: 0.395 | CH8: 0.645 | CI8: 0.815 | CJ8: 0 | CK8: 0.065 | CL8: 0.145 | CM8: 0.245 | CN8: 0.36 | CO8: 0.395 | CP8: 0.645 | CQ8: 0.815 | CR8: 전력 소모량
C9: M1no1 | D9: tb_zrzr | E9: 0.245 | F9: 0.138 | G9: 0.107 | H9: 0.027 | I9: 3648 | J9: 3453 | K9: 48 | L9: 4447 | M9: 5389 | N9: 67 | O9: 71 | P9: 65.5 | Q9: 66 | R9: 48 | S9: 73.5 | T9: =(N4*O4*P4*Q4*R4*S4)/(I4*J4*K4*(F4*H4 + F5*H5 + F6*H6 + F7*H7 + F8*H8 + F9*H9)) -> 4609.9566 | U9: 2.051 | V9: 0.079 | W9: 4.02 | X9: =H5 -> 0.021 | Y9: =H6 -> 0.048 | Z9: =H7 -> 0.027 | AA9: =H8 -> 0.016 | AB9: =H9 -> 0.027 | AC9: =1000000*(O9*Q9*S9)^(1/3)/(I9+0.5*J9+240*K9) -> 4149.0742 | AE9: Score | AF9: =($O9*$Q9*$S9)^(1/3)/(AF4*((1-AF$2)*$H4+AF$2*$H5) + AF6*((1-AF$2)*$H6+AF$2*$H7) + AF8*((1-AF$2)*$H8+AF$2*$H9)) -> 1844.6456 | AG9: =($O9*$Q9*$S9)^(1/3)/(AG4*((1-AG$2)*$H4+AG$2*$H5) + AG6*((1-AG$2)*$H6+AG$2*$H7) + AG8*((1-AG$2)*$H8+AG$2*$H9)) -> 1855.8786 | AH9: =($O9*$Q9*$S9)^(1/3)/(AH4*((1-AH$2)*$H4+AH$2*$H5) + AH6*((1-AH$2)*$H6+AH$2*$H7) + AH8*((1-AH$2)*$H8+AH$2*$H9)) -> 1899.1204 | AI9: =($O9*$Q9*$S9)^(1/3)/(AI4*((1-AI$2)*$H4+AI$2*$H5) + AI6*((1-AI$2)*$H6+AI$2*$H7) + AI8*((1-AI$2)*$H8+AI$2*$H9)) -> 2231.663 | AJ9: =($O9*$Q9*$S9)^(1/3)/(AJ4*((1-AJ$2)*$H4+AJ$2*$H5) + AJ6*((1-AJ$2)*$H6+AJ$2*$H7) + AJ8*((1-AJ$2)*$H8+AJ$2*$H9)) -> 2131.8897 | AK9: =($O9*$Q9*$S9)^(1/3)/(AK4*((1-AK$2)*$H4+AK$2*$H5) + AK6*((1-AK$2)*$H6+AK$2*$H7) + AK8*((1-AK$2)*$H8+AK$2*$H9)) -> 2493.6511 | AL9: =($O9*$Q9*$S9)^(1/3)/(AL4*((1-AL$2)*$H4+AL$2*$H5) + AL6*((1-AL$2)*$H6+AL$2*$H7) + AL8*((1-AL$2)*$H8+AL$2*$H9)) -> 2705.3853 | AM9: =($O9*$Q9*$S9)^(1/3)/(AM4*((1-AM$2)*$H4+AM$2*$H5) + AM6*((1-AM$2)*$H6+AM$2*$H7) + AM8*((1-AM$2)*$H8+AM$2*$H9)) -> 3295.5587 | ... CQ9: =($O9*$Q9*$S9)^(1/3)/(CQ4*((1-CQ$2)*$H4+CQ$2*$H5) + CQ6*((1-CQ$2)*$H6+CQ$2*$H7) + CQ8*((1-CQ$2)*$H8+CQ$2*$H9)) -> 2701.9961 | CR9: 전력 소모율 | CS9: =100*$AF9/AF9 -> 100 | CT9: =100*$AF9/AG9 -> 99.394737 | CU9: =100*$AF9/AH9 -> 97.131579 | CV9: =100*$AF9/AI9 -> 82.657895 | CW9: =100*$AF9/AJ9 -> 86.526316 | CX9: =100*$AF9/AK9 -> 73.973684 | CY9: =100*$AF9/AL9 -> 68.184211 | CZ9: =100*$AF9/AM9 -> 55.973684 | ... FD9: =100*$AF9/CQ9 -> 68.269737
C10: M1no2 | D10: tb_nznz | E10: 0.264 | F10: 0.156 | G10: 0.108 | H10: 0.039 | I10: 3778 | J10: 3517 | K10: 48 | L10: 4568 | M10: 5453 | N10: 67 | O10: 71 | P10: 65.5 | Q10: 66 | R10: 48 | S10: 73.5 | T10: 0 | U10: 2.009 | V10: 0.057 | W10: 4.02 | X10: =H11 -> 0.017 | Y10: =H12 -> 0.048 | Z10: =H13 -> 0.018 | AA10: =H14 -> 0.018 | AB10: =H15 -> 0.018 | AC10: =1000000*(O10*Q10*S10)^(1/3)/(I10+0.5*J10+240*K10) -> 4109.6669 | AE10: NZ rate | AF10: 1 | AG10: 0.815 | AH10: 0.645 | AI10: 0.395 | AJ10: 0.36 | AK10: 0.245 | AL10: 0.145 | AM10: 0.065 | AN10: 1 | AO10: 0.815 | AP10: 0.645 | AQ10: 0.395 | AR10: 0.36 | AS10: 0.245 | AT10: 0.145 | AU10: 0.065 | AV10: 1 | AW10: 0.815 | AX10: 0.645 | AY10: 0.395 | AZ10: 0.36 | BA10: 0.245 | BB10: 0.145 | BC10: 0.065 | BD10: 1 | BE10: 0.815 | BF10: 0.645 | BG10: 0.395 | BH10: 0.36 | BI10: 0.245 | BJ10: 0.145 | BK10: 0.065 | BL10: 1 | BM10: 0.815 | BN10: 0.645 | BO10: 0.395 | BP10: 0.36 | BQ10: 0.245 | BR10: 0.145 | BS10: 0.065 | BT10: 1 | BU10: 0.815 | BV10: 0.645 | BW10: 0.395 | BX10: 0.36 | BY10: 0.245 | BZ10: 0.145 | CA10: 0.065 | CB10: 1 | CC10: 0.815 | CD10: 0.645 | CE10: 0.395 | CF10: 0.36 | CG10: 0.245 | CH10: 0.145 | CI10: 0.065 | CJ10: 1 | CK10: 0.815 | CL10: 0.645 | CM10: 0.395 | CN10: 0.36 | CO10: 0.245 | CP10: 0.145 | CQ10: 0.065
C11: M1no2 | D11: tb_nzzr | E11: 0.235 | F11: 0.128 | G11: 0.107 | H11: 0.017 | I11: 3778 | J11: 3517 | K11: 48 | L11: 4568 | M11: 5453 | N11: 67 | O11: 71 | P11: 65.5 | Q11: 66 | R11: 48 | S11: 73.5 | T11: 0 | U11: 2.009 | V11: 0.057 | W11: 4.02 | X11: =H11 -> 0.017 | Y11: =H12 -> 0.048 | Z11: =H13 -> 0.018 | AA11: =H14 -> 0.018 | AB11: =H15 -> 0.018 | AC11: =1000000*(O11*Q11*S11)^(1/3)/(I11+0.5*J11+240*K11) -> 4109.6669
C12: M1no2 | D12: tb_swnz | E12: 0.273 | F12: 0.166 | G12: 0.108 | H12: 0.048 | I12: 3778 | J12: 3517 | K12: 48 | L12: 4568 | M12: 5453 | N12: 67 | O12: 71 | P12: 65.5 | Q12: 66 | R12: 48 | S12: 73.5 | T12: 0 | U12: 2.009 | V12: 0.057 | W12: 4.02 | X12: =H11 -> 0.017 | Y12: =H12 -> 0.048 | Z12: =H13 -> 0.018 | AA12: =H14 -> 0.018 | AB12: =H15 -> 0.018 | AC12: =1000000*(O12*Q12*S12)^(1/3)/(I12+0.5*J12+240*K12) -> 4109.6669 | AE12: SW rate | AF12: 0 | AG12: 0.12 | AH12: 0.21 | AI12: 0.26 | AJ12: 0.28 | AK12: 0.26 | AL12: 0.21 | AM12: 0.12 | AN12: 0 | AO12: 0.12 | AP12: 0.21 | AQ12: 0.26 | AR12: 0.28 | AS12: 0.26 | AT12: 0.21 | AU12: 0.12 | AV12: 0 | AW12: 0.12 | AX12: 0.21 | AY12: 0.26 | AZ12: 0.28 | BA12: 0.26 | BB12: 0.21 | BC12: 0.12 | BD12: 0 | BE12: 0.12 | BF12: 0.21 | BG12: 0.26 | BH12: 0.28 | BI12: 0.26 | BJ12: 0.21 | BK12: 0.12 | BL12: 0 | BM12: 0.12 | BN12: 0.21 | BO12: 0.26 | BP12: 0.28 | BQ12: 0.26 | BR12: 0.21 | BS12: 0.12 | BT12: 0 | BU12: 0.12 | BV12: 0.21 | BW12: 0.26 | BX12: 0.28 | BY12: 0.26 | BZ12: 0.21 | CA12: 0.12 | CB12: 0 | CC12: 0.12 | CD12: 0.21 | CE12: 0.26 | CF12: 0.28 | CG12: 0.26 | CH12: 0.21 | CI12: 0.12 | CJ12: 0 | CK12: 0.12 | CL12: 0.21 | CM12: 0.26 | CN12: 0.28 | CO12: 0.26 | CP12: 0.21 | CQ12: 0.12
C13: M1no2 | D13: tb_swzr | E13: 0.236 | F13: 0.129 | G13: 0.107 | H13: 0.018 | I13: 3778 | J13: 3517 | K13: 48 | L13: 4568 | M13: 5453 | N13: 67 | O13: 71 | P13: 65.5 | Q13: 66 | R13: 48 | S13: 73.5 | T13: 0 | U13: 2.009 | V13: 0.057 | W13: 4.02 | X13: =H11 -> 0.017 | Y13: =H12 -> 0.048 | Z13: =H13 -> 0.018 | AA13: =H14 -> 0.018 | AB13: =H15 -> 0.018 | AC13: =1000000*(O13*Q13*S13)^(1/3)/(I13+0.5*J13+240*K13) -> 4109.6669
C14: M1no2 | D14: tb_zrnz | E14: 0.236 | F14: 0.129 | G14: 0.107 | H14: 0.018 | I14: 3778 | J14: 3517 | K14: 48 | L14: 4568 | M14: 5453 | N14: 67 | O14: 71 | P14: 65.5 | Q14: 66 | R14: 48 | S14: 73.5 | T14: 0 | U14: 2.009 | V14: 0.057 | W14: 4.02 | X14: =H11 -> 0.017 | Y14: =H12 -> 0.048 | Z14: =H13 -> 0.018 | AA14: =H14 -> 0.018 | AB14: =H15 -> 0.018 | AC14: =1000000*(O14*Q14*S14)^(1/3)/(I14+0.5*J14+240*K14) -> 4109.6669 | AE14: ZR rate | AF14: 0 | AG14: 0.065 | AH14: 0.145 | AI14: 0.245 | AJ14: 0.36 | AK14: 0.395 | AL14: 0.645 | AM14: 0.815 | AN14: 0 | AO14: 0.065 | AP14: 0.145 | AQ14: 0.245 | AR14: 0.36 | AS14: 0.395 | AT14: 0.645 | AU14: 0.815 | AV14: 0 | AW14: 0.065 | AX14: 0.145 | AY14: 0.245 | AZ14: 0.36 | BA14: 0.395 | BB14: 0.645 | BC14: 0.815 | BD14: 0 | BE14: 0.065 | BF14: 0.145 | BG14: 0.245 | BH14: 0.36 | BI14: 0.395 | BJ14: 0.645 | BK14: 0.815 | BL14: 0 | BM14: 0.065 | BN14: 0.145 | BO14: 0.245 | BP14: 0.36 | BQ14: 0.395 | BR14: 0.645 | BS14: 0.815 | BT14: 0 | BU14: 0.065 | BV14: 0.145 | BW14: 0.245 | BX14: 0.36 | BY14: 0.395 | BZ14: 0.645 | CA14: 0.815 | CB14: 0 | CC14: 0.065 | CD14: 0.145 | CE14: 0.245 | CF14: 0.36 | CG14: 0.395 | CH14: 0.645 | CI14: 0.815 | CJ14: 0 | CK14: 0.065 | CL14: 0.145 | CM14: 0.245 | CN14: 0.36 | CO14: 0.395 | CP14: 0.645 | CQ14: 0.815
C15: M1no2 | D15: tb_zrzr | E15: 0.236 | F15: 0.129 | G15: 0.107 | H15: 0.018 | I15: 3778 | J15: 3517 | K15: 48 | L15: 4568 | M15: 5453 | N15: 67 | O15: 71 | P15: 65.5 | Q15: 66 | R15: 48 | S15: 73.5 | T15: =(N10*O10*P10*Q10*R10*S10)/(I10*J10*K10*(F10*H10 + F11*H11 + F12*H12 + F13*H13 + F14*H14 + F15*H15)) -> 4904.5114 | U15: 2.009 | V15: 0.057 | W15: 4.02 | X15: =H11 -> 0.017 | Y15: =H12 -> 0.048 | Z15: =H13 -> 0.018 | AA15: =H14 -> 0.018 | AB15: =H15 -> 0.018 | AC15: =1000000*(O15*Q15*S15)^(1/3)/(I15+0.5*J15+240*K15) -> 4109.6669 | AE15: Score | AF15: =($O15*$Q15*$S15)^(1/3)/(AF10*((1-AF$2)*$H10+AF$2*$H11) + AF12*((1-AF$2)*$H12+AF$2*$H13) + AF14*((1-AF$2)*$H14+AF$2*$H15)) -> 1797.347 | AG15: =($O15*$Q15*$S15)^(1/3)/(AG10*((1-AG$2)*$H10+AG$2*$H11) + AG12*((1-AG$2)*$H12+AG$2*$H13) + AG14*((1-AG$2)*$H14+AG$2*$H15)) -> 1810.5782 | AH15: =($O15*$Q15*$S15)^(1/3)/(AH10*((1-AH$2)*$H10+AH$2*$H11) + AH12*((1-AH$2)*$H12+AH$2*$H13) + AH14*((1-AH$2)*$H14+AH$2*$H15)) -> 1852.2006 | AI15: =($O15*$Q15*$S15)^(1/3)/(AI10*((1-AI$2)*$H10+AI$2*$H11) + AI12*((1-AI$2)*$H12+AI$2*$H13) + AI14*((1-AI$2)*$H14+AI$2*$H15)) -> 2170.5073 | AJ15: =($O15*$Q15*$S15)^(1/3)/(AJ10*((1-AJ$2)*$H10+AJ$2*$H11) + AJ12*((1-AJ$2)*$H12+AJ$2*$H13) + AJ14*((1-AJ$2)*$H14+AJ$2*$H15)) -> 2064.0911 | AK15: =($O15*$Q15*$S15)^(1/3)/(AK10*((1-AK$2)*$H10+AK$2*$H11) + AK12*((1-AK$2)*$H12+AK$2*$H13) + AK14*((1-AK$2)*$H14+AK$2*$H15)) -> 2405.0964 | AL15: =($O15*$Q15*$S15)^(1/3)/(AL10*((1-AL$2)*$H10+AL$2*$H11) + AL12*((1-AL$2)*$H12+AL$2*$H13) + AL14*((1-AL$2)*$H14+AL$2*$H15)) -> 2563.4132 | AM15: =($O15*$Q15*$S15)^(1/3)/(AM10*((1-AM$2)*$H10+AM$2*$H11) + AM12*((1-AM$2)*$H12+AM$2*$H13) + AM14*((1-AM$2)*$H14+AM$2*$H15)) -> 3052.3202 | ... CQ15: =($O15*$Q15*$S15)^(1/3)/(CQ10*((1-CQ$2)*$H10+CQ$2*$H11) + CQ12*((1-CQ$2)*$H12+CQ$2*$H13) + CQ14*((1-CQ$2)*$H14+CQ$2*$H15)) -> 3775.99 | CS15: =100*$AF15/AF15 -> 100 | CT15: =100*$AF15/AG15 -> 99.269231 | CU15: =100*$AF15/AH15 -> 97.038462 | CV15: =100*$AF15/AI15 -> 82.807692 | CW15: =100*$AF15/AJ15 -> 87.076923 | CX15: =100*$AF15/AK15 -> 74.730769 | CY15: =100*$AF15/AL15 -> 70.115385 | CZ15: =100*$AF15/AM15 -> 58.884615 | ... FD15: =100*$AF15/CQ15 -> 47.599359
C16: M1no3 | D16: tb_nznz | E16: 0.265 | F16: 0.157 | G16: 0.108 | H16: 0.04 | I16: 3839 | J16: 3637 | K16: 48 | L16: 4637 | M16: 5573 | N16: 67 | O16: 71 | P16: 65.5 | Q16: 66 | R16: 48 | S16: 73.5 | T16: 0 | U16: 2.075 | V16: 0.059 | W16: 4.02 | X16: =H17 -> 0.018 | Y16: =H18 -> 0.048 | Z16: =H19 -> 0.019 | AA16: =H20 -> 0.019 | AB16: =H21 -> 0.019 | AC16: =1000000*(O16*Q16*S16)^(1/3)/(I16+0.5*J16+240*K16) -> 4080.718 | AE16: NZ rate | AF16: 1 | AG16: 0.815 | AH16: 0.645 | AI16: 0.395 | AJ16: 0.36 | AK16: 0.245 | AL16: 0.145 | AM16: 0.065 | AN16: 1 | AO16: 0.815 | AP16: 0.645 | AQ16: 0.395 | AR16: 0.36 | AS16: 0.245 | AT16: 0.145 | AU16: 0.065 | AV16: 1 | AW16: 0.815 | AX16: 0.645 | AY16: 0.395 | AZ16: 0.36 | BA16: 0.245 | BB16: 0.145 | BC16: 0.065 | BD16: 1 | BE16: 0.815 | BF16: 0.645 | BG16: 0.395 | BH16: 0.36 | BI16: 0.245 | BJ16: 0.145 | BK16: 0.065 | BL16: 1 | BM16: 0.815 | BN16: 0.645 | BO16: 0.395 | BP16: 0.36 | BQ16: 0.245 | BR16: 0.145 | BS16: 0.065 | BT16: 1 | BU16: 0.815 | BV16: 0.645 | BW16: 0.395 | BX16: 0.36 | BY16: 0.245 | BZ16: 0.145 | CA16: 0.065 | CB16: 1 | CC16: 0.815 | CD16: 0.645 | CE16: 0.395 | CF16: 0.36 | CG16: 0.245 | CH16: 0.145 | CI16: 0.065 | CJ16: 1 | CK16: 0.815 | CL16: 0.645 | CM16: 0.395 | CN16: 0.36 | CO16: 0.245 | CP16: 0.145 | CQ16: 0.065
C17: M1no3 | D17: tb_nzzr | E17: 0.235 | F17: 0.128 | G17: 0.107 | H17: 0.018 | I17: 3839 | J17: 3637 | K17: 48 | L17: 4637 | M17: 5573 | N17: 67 | O17: 71 | P17: 65.5 | Q17: 66 | R17: 48 | S17: 73.5 | T17: 0 | U17: 2.075 | V17: 0.059 | W17: 4.02 | X17: =H17 -> 0.018 | Y17: =H18 -> 0.048 | Z17: =H19 -> 0.019 | AA17: =H20 -> 0.019 | AB17: =H21 -> 0.019 | AC17: =1000000*(O17*Q17*S17)^(1/3)/(I17+0.5*J17+240*K17) -> 4080.718
C18: M1no3 | D18: tb_swnz | E18: 0.274 | F18: 0.166 | G18: 0.108 | H18: 0.048 | I18: 3839 | J18: 3637 | K18: 48 | L18: 4637 | M18: 5573 | N18: 67 | O18: 71 | P18: 65.5 | Q18: 66 | R18: 48 | S18: 73.5 | T18: 0 | U18: 2.075 | V18: 0.059 | W18: 4.02 | X18: =H17 -> 0.018 | Y18: =H18 -> 0.048 | Z18: =H19 -> 0.019 | AA18: =H20 -> 0.019 | AB18: =H21 -> 0.019 | AC18: =1000000*(O18*Q18*S18)^(1/3)/(I18+0.5*J18+240*K18) -> 4080.718 | AE18: SW rate | AF18: 0 | AG18: 0.12 | AH18: 0.21 | AI18: 0.26 | AJ18: 0.28 | AK18: 0.26 | AL18: 0.21 | AM18: 0.12 | AN18: 0 | AO18: 0.12 | AP18: 0.21 | AQ18: 0.26 | AR18: 0.28 | AS18: 0.26 | AT18: 0.21 | AU18: 0.12 | AV18: 0 | AW18: 0.12 | AX18: 0.21 | AY18: 0.26 | AZ18: 0.28 | BA18: 0.26 | BB18: 0.21 | BC18: 0.12 | BD18: 0 | BE18: 0.12 | BF18: 0.21 | BG18: 0.26 | BH18: 0.28 | BI18: 0.26 | BJ18: 0.21 | BK18: 0.12 | BL18: 0 | BM18: 0.12 | BN18: 0.21 | BO18: 0.26 | BP18: 0.28 | BQ18: 0.26 | BR18: 0.21 | BS18: 0.12 | BT18: 0 | BU18: 0.12 | BV18: 0.21 | BW18: 0.26 | BX18: 0.28 | BY18: 0.26 | BZ18: 0.21 | CA18: 0.12 | CB18: 0 | CC18: 0.12 | CD18: 0.21 | CE18: 0.26 | CF18: 0.28 | CG18: 0.26 | CH18: 0.21 | CI18: 0.12 | CJ18: 0 | CK18: 0.12 | CL18: 0.21 | CM18: 0.26 | CN18: 0.28 | CO18: 0.26 | CP18: 0.21 | CQ18: 0.12
C19: M1no3 | D19: tb_swzr | E19: 0.237 | F19: 0.129 | G19: 0.107 | H19: 0.019 | I19: 3839 | J19: 3637 | K19: 48 | L19: 4637 | M19: 5573 | N19: 67 | O19: 71 | P19: 65.5 | Q19: 66 | R19: 48 | S19: 73.5 | T19: 0 | U19: 2.075 | V19: 0.059 | W19: 4.02 | X19: =H17 -> 0.018 | Y19: =H18 -> 0.048 | Z19: =H19 -> 0.019 | AA19: =H20 -> 0.019 | AB19: =H21 -> 0.019 | AC19: =1000000*(O19*Q19*S19)^(1/3)/(I19+0.5*J19+240*K19) -> 4080.718
C20: M1no3 | D20: tb_zrnz | E20: 0.236 | F20: 0.129 | G20: 0.107 | H20: 0.019 | I20: 3839 | J20: 3637 | K20: 48 | L20: 4637 | M20: 5573 | N20: 67 | O20: 71 | P20: 65.5 | Q20: 66 | R20: 48 | S20: 73.5 | T20: 0 | U20: 2.075 | V20: 0.059 | W20: 4.02 | X20: =H17 -> 0.018 | Y20: =H18 -> 0.048 | Z20: =H19 -> 0.019 | AA20: =H20 -> 0.019 | AB20: =H21 -> 0.019 | AC20: =1000000*(O20*Q20*S20)^(1/3)/(I20+0.5*J20+240*K20) -> 4080.718 | AE20: ZR rate | AF20: 0 | AG20: 0.065 | AH20: 0.145 | AI20: 0.245 | AJ20: 0.36 | AK20: 0.395 | AL20: 0.645 | AM20: 0.815 | AN20: 0 | AO20: 0.065 | AP20: 0.145 | AQ20: 0.245 | AR20: 0.36 | AS20: 0.395 | AT20: 0.645 | AU20: 0.815 | AV20: 0 | AW20: 0.065 | AX20: 0.145 | AY20: 0.245 | AZ20: 0.36 | BA20: 0.395 | BB20: 0.645 | BC20: 0.815 | BD20: 0 | BE20: 0.065 | BF20: 0.145 | BG20: 0.245 | BH20: 0.36 | BI20: 0.395 | BJ20: 0.645 | BK20: 0.815 | BL20: 0 | BM20: 0.065 | BN20: 0.145 | BO20: 0.245 | BP20: 0.36 | BQ20: 0.395 | BR20: 0.645 | BS20: 0.815 | BT20: 0 | BU20: 0.065 | BV20: 0.145 | BW20: 0.245 | BX20: 0.36 | BY20: 0.395 | BZ20: 0.645 | CA20: 0.815 | CB20: 0 | CC20: 0.065 | CD20: 0.145 | CE20: 0.245 | CF20: 0.36 | CG20: 0.395 | CH20: 0.645 | CI20: 0.815 | CJ20: 0 | CK20: 0.065 | CL20: 0.145 | CM20: 0.245 | CN20: 0.36 | CO20: 0.395 | CP20: 0.645 | CQ20: 0.815
C21: M1no3 | D21: tb_zrzr | E21: 0.237 | F21: 0.129 | G21: 0.107 | H21: 0.019 | I21: 3839 | J21: 3637 | K21: 48 | L21: 4637 | M21: 5573 | N21: 67 | O21: 71 | P21: 65.5 | Q21: 66 | R21: 48 | S21: 73.5 | T21: =(N16*O16*P16*Q16*R16*S16)/(I16*J16*K16*(F16*H16 + F17*H17 + F18*H18 + F19*H19 + F20*H20 + F21*H21)) -> 4528.5124 | U21: 2.075 | V21: 0.059 | W21: 4.02 | X21: =H17 -> 0.018 | Y21: =H18 -> 0.048 | Z21: =H19 -> 0.019 | AA21: =H20 -> 0.019 | AB21: =H21 -> 0.019 | AC21: =1000000*(O21*Q21*S21)^(1/3)/(I21+0.5*J21+240*K21) -> 4080.718 | AE21: Score | AF21: =($O21*$Q21*$S21)^(1/3)/(AF16*((1-AF$2)*$H16+AF$2*$H17) + AF18*((1-AF$2)*$H18+AF$2*$H19) + AF20*((1-AF$2)*$H20+AF$2*$H21)) -> 1752.4133 | AG21: =($O21*$Q21*$S21)^(1/3)/(AG16*((1-AG$2)*$H16+AG$2*$H17) + AG18*((1-AG$2)*$H18+AG$2*$H19) + AG20*((1-AG$2)*$H20+AG$2*$H21)) -> 1770.338 | AH21: =($O21*$Q21*$S21)^(1/3)/(AH16*((1-AH$2)*$H16+AH$2*$H17) + AH18*((1-AH$2)*$H18+AH$2*$H19) + AH20*((1-AH$2)*$H20+AH$2*$H21)) -> 1814.3273 | AI21: =($O21*$Q21*$S21)^(1/3)/(AI16*((1-AI$2)*$H16+AI$2*$H17) + AI18*((1-AI$2)*$H18+AI$2*$H19) + AI20*((1-AI$2)*$H20+AI$2*$H21)) -> 2128.3295 | AJ21: =($O21*$Q21*$S21)^(1/3)/(AJ16*((1-AJ$2)*$H16+AJ$2*$H17) + AJ18*((1-AJ$2)*$H18+AJ$2*$H19) + AJ20*((1-AJ$2)*$H20+AJ$2*$H21)) -> 2021.238 | AK21: =($O21*$Q21*$S21)^(1/3)/(AK16*((1-AK$2)*$H16+AK$2*$H17) + AK18*((1-AK$2)*$H18+AK$2*$H19) + AK20*((1-AK$2)*$H20+AK$2*$H21)) -> 2353.4173 | AL21: =($O21*$Q21*$S21)^(1/3)/(AL16*((1-AL$2)*$H16+AL$2*$H17) + AL18*((1-AL$2)*$H18+AL$2*$H19) + AL20*((1-AL$2)*$H20+AL$2*$H21)) -> 2491.4353 | AM21: =($O21*$Q21*$S21)^(1/3)/(AM16*((1-AM$2)*$H16+AM$2*$H17) + AM18*((1-AM$2)*$H18+AM$2*$H19) + AM20*((1-AM$2)*$H20+AM$2*$H21)) -> 2939.6743 | ... CQ21: =($O21*$Q21*$S21)^(1/3)/(CQ16*((1-CQ$2)*$H16+CQ$2*$H17) + CQ18*((1-CQ$2)*$H18+CQ$2*$H19) + CQ20*((1-CQ$2)*$H20+CQ$2*$H21)) -> 3585.7297 | CS21: =100*$AF21/AF21 -> 100 | CT21: =100*$AF21/AG21 -> 98.9875 | CU21: =100*$AF21/AH21 -> 96.5875 | CV21: =100*$AF21/AI21 -> 82.3375 | CW21: =100*$AF21/AJ21 -> 86.7 | CX21: =100*$AF21/AK21 -> 74.4625 | CY21: =100*$AF21/AL21 -> 70.3375 | CZ21: =100*$AF21/AM21 -> 59.6125 | ... FD21: =100*$AF21/CQ21 -> 48.871875
C22: M1no4 | D22: tb_nznz | E22: 0.264 | F22: 0.156 | G22: 0.108 | H22: 0.039 | I22: 3777 | J22: 3517 | K22: 48 | L22: 4565 | M22: 5453 | N22: 67 | O22: 71 | P22: 65.5 | Q22: 66 | R22: 48 | S22: 73.5 | T22: 0 | U22: 1.906 | V22: 0.022 | W22: 4.02 | X22: =H23 -> 0.023 | Y22: =H24 -> 0.038 | Z22: =H25 -> 0.024 | AA22: =H26 -> 0.016 | AB22: =H27 -> 0.024 | AC22: =1000000*(O22*Q22*S22)^(1/3)/(I22+0.5*J22+240*K22) -> 4109.9079 | AE22: NZ rate | AF22: 1 | AG22: 0.815 | AH22: 0.645 | AI22: 0.395 | AJ22: 0.36 | AK22: 0.245 | AL22: 0.145 | AM22: 0.065 | AN22: 1 | AO22: 0.815 | AP22: 0.645 | AQ22: 0.395 | AR22: 0.36 | AS22: 0.245 | AT22: 0.145 | AU22: 0.065 | AV22: 1 | AW22: 0.815 | AX22: 0.645 | AY22: 0.395 | AZ22: 0.36 | BA22: 0.245 | BB22: 0.145 | BC22: 0.065 | BD22: 1 | BE22: 0.815 | BF22: 0.645 | BG22: 0.395 | BH22: 0.36 | BI22: 0.245 | BJ22: 0.145 | BK22: 0.065 | BL22: 1 | BM22: 0.815 | BN22: 0.645 | BO22: 0.395 | BP22: 0.36 | BQ22: 0.245 | BR22: 0.145 | BS22: 0.065 | BT22: 1 | BU22: 0.815 | BV22: 0.645 | BW22: 0.395 | BX22: 0.36 | BY22: 0.245 | BZ22: 0.145 | CA22: 0.065 | CB22: 1 | CC22: 0.815 | CD22: 0.645 | CE22: 0.395 | CF22: 0.36 | CG22: 0.245 | CH22: 0.145 | CI22: 0.065 | CJ22: 1 | CK22: 0.815 | CL22: 0.645 | CM22: 0.395 | CN22: 0.36 | CO22: 0.245 | CP22: 0.145 | CQ22: 0.065
C23: M1no4 | D23: tb_nzzr | E23: 0.241 | F23: 0.134 | G23: 0.107 | H23: 0.023 | I23: 3777 | J23: 3517 | K23: 48 | L23: 4565 | M23: 5453 | N23: 67 | O23: 71 | P23: 65.5 | Q23: 66 | R23: 48 | S23: 73.5 | T23: 0 | U23: 1.906 | V23: 0.022 | W23: 4.02 | X23: =H23 -> 0.023 | Y23: =H24 -> 0.038 | Z23: =H25 -> 0.024 | AA23: =H26 -> 0.016 | AB23: =H27 -> 0.024 | AC23: =1000000*(O23*Q23*S23)^(1/3)/(I23+0.5*J23+240*K23) -> 4109.9079
C24: M1no4 | D24: tb_swnz | E24: 0.263 | F24: 0.155 | G24: 0.108 | H24: 0.038 | I24: 3777 | J24: 3517 | K24: 48 | L24: 4565 | M24: 5453 | N24: 67 | O24: 71 | P24: 65.5 | Q24: 66 | R24: 48 | S24: 73.5 | T24: 0 | U24: 1.906 | V24: 0.022 | W24: 4.02 | X24: =H23 -> 0.023 | Y24: =H24 -> 0.038 | Z24: =H25 -> 0.024 | AA24: =H26 -> 0.016 | AB24: =H27 -> 0.024 | AC24: =1000000*(O24*Q24*S24)^(1/3)/(I24+0.5*J24+240*K24) -> 4109.9079 | AE24: SW rate | AF24: 0 | AG24: 0.12 | AH24: 0.21 | AI24: 0.26 | AJ24: 0.28 | AK24: 0.26 | AL24: 0.21 | AM24: 0.12 | AN24: 0 | AO24: 0.12 | AP24: 0.21 | AQ24: 0.26 | AR24: 0.28 | AS24: 0.26 | AT24: 0.21 | AU24: 0.12 | AV24: 0 | AW24: 0.12 | AX24: 0.21 | AY24: 0.26 | AZ24: 0.28 | BA24: 0.26 | BB24: 0.21 | BC24: 0.12 | BD24: 0 | BE24: 0.12 | BF24: 0.21 | BG24: 0.26 | BH24: 0.28 | BI24: 0.26 | BJ24: 0.21 | BK24: 0.12 | BL24: 0 | BM24: 0.12 | BN24: 0.21 | BO24: 0.26 | BP24: 0.28 | BQ24: 0.26 | BR24: 0.21 | BS24: 0.12 | BT24: 0 | BU24: 0.12 | BV24: 0.21 | BW24: 0.26 | BX24: 0.28 | BY24: 0.26 | BZ24: 0.21 | CA24: 0.12 | CB24: 0 | CC24: 0.12 | CD24: 0.21 | CE24: 0.26 | CF24: 0.28 | CG24: 0.26 | CH24: 0.21 | CI24: 0.12 | CJ24: 0 | CK24: 0.12 | CL24: 0.21 | CM24: 0.26 | CN24: 0.28 | CO24: 0.26 | CP24: 0.21 | CQ24: 0.12
C25: M1no4 | D25: tb_swzr | E25: 0.242 | F25: 0.135 | G25: 0.107 | H25: 0.024 | I25: 3777 | J25: 3517 | K25: 48 | L25: 4565 | M25: 5453 | N25: 67 | O25: 71 | P25: 65.5 | Q25: 66 | R25: 48 | S25: 73.5 | T25: 0 | U25: 1.906 | V25: 0.022 | W25: 4.02 | X25: =H23 -> 0.023 | Y25: =H24 -> 0.038 | Z25: =H25 -> 0.024 | AA25: =H26 -> 0.016 | AB25: =H27 -> 0.024 | AC25: =1000000*(O25*Q25*S25)^(1/3)/(I25+0.5*J25+240*K25) -> 4109.9079
C26: M1no4 | D26: tb_zrnz | E26: 0.233 | F26: 0.126 | G26: 0.107 | H26: 0.016 | I26: 3777 | J26: 3517 | K26: 48 | L26: 4565 | M26: 5453 | N26: 67 | O26: 71 | P26: 65.5 | Q26: 66 | R26: 48 | S26: 73.5 | T26: 0 | U26: 1.906 | V26: 0.022 | W26: 4.02 | X26: =H23 -> 0.023 | Y26: =H24 -> 0.038 | Z26: =H25 -> 0.024 | AA26: =H26 -> 0.016 | AB26: =H27 -> 0.024 | AC26: =1000000*(O26*Q26*S26)^(1/3)/(I26+0.5*J26+240*K26) -> 4109.9079 | AE26: ZR rate | AF26: 0 | AG26: 0.065 | AH26: 0.145 | AI26: 0.245 | AJ26: 0.36 | AK26: 0.395 | AL26: 0.645 | AM26: 0.815 | AN26: 0 | AO26: 0.065 | AP26: 0.145 | AQ26: 0.245 | AR26: 0.36 | AS26: 0.395 | AT26: 0.645 | AU26: 0.815 | AV26: 0 | AW26: 0.065 | AX26: 0.145 | AY26: 0.245 | AZ26: 0.36 | BA26: 0.395 | BB26: 0.645 | BC26: 0.815 | BD26: 0 | BE26: 0.065 | BF26: 0.145 | BG26: 0.245 | BH26: 0.36 | BI26: 0.395 | BJ26: 0.645 | BK26: 0.815 | BL26: 0 | BM26: 0.065 | BN26: 0.145 | BO26: 0.245 | BP26: 0.36 | BQ26: 0.395 | BR26: 0.645 | BS26: 0.815 | BT26: 0 | BU26: 0.065 | BV26: 0.145 | BW26: 0.245 | BX26: 0.36 | BY26: 0.395 | BZ26: 0.645 | CA26: 0.815 | CB26: 0 | CC26: 0.065 | CD26: 0.145 | CE26: 0.245 | CF26: 0.36 | CG26: 0.395 | CH26: 0.645 | CI26: 0.815 | CJ26: 0 | CK26: 0.065 | CL26: 0.145 | CM26: 0.245 | CN26: 0.36 | CO26: 0.395 | CP26: 0.645 | CQ26: 0.815
C27: M1no4 | D27: tb_zrzr | E27: 0.242 | F27: 0.135 | G27: 0.107 | H27: 0.024 | I27: 3777 | J27: 3517 | K27: 48 | L27: 4565 | M27: 5453 | N27: 67 | O27: 71 | P27: 65.5 | Q27: 66 | R27: 48 | S27: 73.5 | T27: =(N22*O22*P22*Q22*R22*S22)/(I22*J22*K22*(F22*H22 + F23*H23 + F24*H24 + F25*H25 + F26*H26 + F27*H27)) -> 4831.2396 | U27: 1.906 | V27: 0.022 | W27: 4.02 | X27: =H23 -> 0.023 | Y27: =H24 -> 0.038 | Z27: =H25 -> 0.024 | AA27: =H26 -> 0.016 | AB27: =H27 -> 0.024 | AC27: =1000000*(O27*Q27*S27)^(1/3)/(I27+0.5*J27+240*K27) -> 4109.9079 | AE27: Score | AF27: =($O27*$Q27*$S27)^(1/3)/(AF22*((1-AF$2)*$H22+AF$2*$H23) + AF24*((1-AF$2)*$H24+AF$2*$H25) + AF26*((1-AF$2)*$H26+AF$2*$H27)) -> 1797.347 | AG27: =($O27*$Q27*$S27)^(1/3)/(AG22*((1-AG$2)*$H22+AG$2*$H23) + AG24*((1-AG$2)*$H24+AG$2*$H25) + AG26*((1-AG$2)*$H26+AG$2*$H27)) -> 1874.9909 | AH27: =($O27*$Q27*$S27)^(1/3)/(AH22*((1-AH$2)*$H22+AH$2*$H23) + AH24*((1-AH$2)*$H24+AH$2*$H25) + AH26*((1-AH$2)*$H26+AH$2*$H27)) -> 1977.0564 | AI27: =($O27*$Q27*$S27)^(1/3)/(AI22*((1-AI$2)*$H22+AI$2*$H23) + AI24*((1-AI$2)*$H24+AI$2*$H25) + AI26*((1-AI$2)*$H26+AI$2*$H27)) -> 2400.1552 | AJ27: =($O27*$Q27*$S27)^(1/3)/(AJ22*((1-AJ$2)*$H22+AJ$2*$H23) + AJ24*((1-AJ$2)*$H24+AJ$2*$H25) + AJ26*((1-AJ$2)*$H26+AJ$2*$H27)) -> 2302.7771 | AK27: =($O27*$Q27*$S27)^(1/3)/(AK22*((1-AK$2)*$H22+AK$2*$H23) + AK24*((1-AK$2)*$H24+AK$2*$H25) + AK26*((1-AK$2)*$H26+AK$2*$H27)) -> 2721.667 | AL27: =($O27*$Q27*$S27)^(1/3)/(AL22*((1-AL$2)*$H22+AL$2*$H23) + AL24*((1-AL$2)*$H24+AL$2*$H25) + AL26*((1-AL$2)*$H26+AL$2*$H27)) -> 2926.1755 | AM27: =($O27*$Q27*$S27)^(1/3)/(AM22*((1-AM$2)*$H22+AM$2*$H23) + AM24*((1-AM$2)*$H24+AM$2*$H25) + AM26*((1-AM$2)*$H26+AM$2*$H27)) -> 3481.3277 | ... CQ27: =($O27*$Q27*$S27)^(1/3)/(CQ22*((1-CQ$2)*$H22+CQ$2*$H23) + CQ24*((1-CQ$2)*$H24+CQ$2*$H25) + CQ26*((1-CQ$2)*$H26+CQ$2*$H27)) -> 2987.917 | CS27: =100*$AF27/AF27 -> 100 | CT27: =100*$AF27/AG27 -> 95.858974 | CU27: =100*$AF27/AH27 -> 90.910256 | CV27: =100*$AF27/AI27 -> 74.884615 | CW27: =100*$AF27/AJ27 -> 78.051282 | CX27: =100*$AF27/AK27 -> 66.038462 | CY27: =100*$AF27/AL27 -> 61.423077 | CZ27: =100*$AF27/AM27 -> 51.628205 | ... FD27: =100*$AF27/CQ27 -> 60.153846
C28: M1no5 | D28: tb_nznz | E28: 0.261 | F28: 0.154 | G28: 0.108 | H28: 0.037 | I28: 3784 | J28: 3453 | K28: 48 | L28: 4564 | M28: 5389 | N28: 67 | O28: 71 | P28: 65.5 | Q28: 66 | R28: 48 | S28: 73.5 | T28: 0 | U28: 2.037 | V28: 0.07 | W28: 4.02 | X28: =H29 -> 0.016 | Y28: =H30 -> 0.036 | Z28: =H31 -> 0.017 | AA28: =H32 -> 0.015 | AB28: =H33 -> 0.017 | AC28: =1000000*(O28*Q28*S28)^(1/3)/(I28+0.5*J28+240*K28) -> 4115.941 | AE28: NZ rate | AF28: 1 | AG28: 0.815 | AH28: 0.645 | AI28: 0.395 | AJ28: 0.36 | AK28: 0.245 | AL28: 0.145 | AM28: 0.065 | AN28: 1 | AO28: 0.815 | AP28: 0.645 | AQ28: 0.395 | AR28: 0.36 | AS28: 0.245 | AT28: 0.145 | AU28: 0.065 | AV28: 1 | AW28: 0.815 | AX28: 0.645 | AY28: 0.395 | AZ28: 0.36 | BA28: 0.245 | BB28: 0.145 | BC28: 0.065 | BD28: 1 | BE28: 0.815 | BF28: 0.645 | BG28: 0.395 | BH28: 0.36 | BI28: 0.245 | BJ28: 0.145 | BK28: 0.065 | BL28: 1 | BM28: 0.815 | BN28: 0.645 | BO28: 0.395 | BP28: 0.36 | BQ28: 0.245 | BR28: 0.145 | BS28: 0.065 | BT28: 1 | BU28: 0.815 | BV28: 0.645 | BW28: 0.395 | BX28: 0.36 | BY28: 0.245 | BZ28: 0.145 | CA28: 0.065 | CB28: 1 | CC28: 0.815 | CD28: 0.645 | CE28: 0.395 | CF28: 0.36 | CG28: 0.245 | CH28: 0.145 | CI28: 0.065 | CJ28: 1 | CK28: 0.815 | CL28: 0.645 | CM28: 0.395 | CN28: 0.36 | CO28: 0.245 | CP28: 0.145 | CQ28: 0.065
C29: M1no5 | D29: tb_nzzr | E29: 0.232 | F29: 0.125 | G29: 0.107 | H29: 0.016 | I29: 3784 | J29: 3453 | K29: 48 | L29: 4564 | M29: 5389 | N29: 67 | O29: 71 | P29: 65.5 | Q29: 66 | R29: 48 | S29: 73.5 | T29: 0 | U29: 2.037 | V29: 0.07 | W29: 4.02 | X29: =H29 -> 0.016 | Y29: =H30 -> 0.036 | Z29: =H31 -> 0.017 | AA29: =H32 -> 0.015 | AB29: =H33 -> 0.017 | AC29: =1000000*(O29*Q29*S29)^(1/3)/(I29+0.5*J29+240*K29) -> 4115.941
C30: M1no5 | D30: tb_swnz | E30: 0.261 | F30: 0.153 | G30: 0.108 | H30: 0.036 | I30: 3784 | J30: 3453 | K30: 48 | L30: 4564 | M30: 5389 | N30: 67 | O30: 71 | P30: 65.5 | Q30: 66 | R30: 48 | S30: 73.5 | T30: 0 | U30: 2.037 | V30: 0.07 | W30: 4.02 | X30: =H29 -> 0.016 | Y30: =H30 -> 0.036 | Z30: =H31 -> 0.017 | AA30: =H32 -> 0.015 | AB30: =H33 -> 0.017 | AC30: =1000000*(O30*Q30*S30)^(1/3)/(I30+0.5*J30+240*K30) -> 4115.941 | AE30: SW rate | AF30: 0 | AG30: 0.12 | AH30: 0.21 | AI30: 0.26 | AJ30: 0.28 | AK30: 0.26 | AL30: 0.21 | AM30: 0.12 | AN30: 0 | AO30: 0.12 | AP30: 0.21 | AQ30: 0.26 | AR30: 0.28 | AS30: 0.26 | AT30: 0.21 | AU30: 0.12 | AV30: 0 | AW30: 0.12 | AX30: 0.21 | AY30: 0.26 | AZ30: 0.28 | BA30: 0.26 | BB30: 0.21 | BC30: 0.12 | BD30: 0 | BE30: 0.12 | BF30: 0.21 | BG30: 0.26 | BH30: 0.28 | BI30: 0.26 | BJ30: 0.21 | BK30: 0.12 | BL30: 0 | BM30: 0.12 | BN30: 0.21 | BO30: 0.26 | BP30: 0.28 | BQ30: 0.26 | BR30: 0.21 | BS30: 0.12 | BT30: 0 | BU30: 0.12 | BV30: 0.21 | BW30: 0.26 | BX30: 0.28 | BY30: 0.26 | BZ30: 0.21 | CA30: 0.12 | CB30: 0 | CC30: 0.12 | CD30: 0.21 | CE30: 0.26 | CF30: 0.28 | CG30: 0.26 | CH30: 0.21 | CI30: 0.12 | CJ30: 0 | CK30: 0.12 | CL30: 0.21 | CM30: 0.26 | CN30: 0.28 | CO30: 0.26 | CP30: 0.21 | CQ30: 0.12
C31: M1no5 | D31: tb_swzr | E31: 0.234 | F31: 0.127 | G31: 0.107 | H31: 0.017 | I31: 3784 | J31: 3453 | K31: 48 | L31: 4564 | M31: 5389 | N31: 67 | O31: 71 | P31: 65.5 | Q31: 66 | R31: 48 | S31: 73.5 | T31: 0 | U31: 2.037 | V31: 0.07 | W31: 4.02 | X31: =H29 -> 0.016 | Y31: =H30 -> 0.036 | Z31: =H31 -> 0.017 | AA31: =H32 -> 0.015 | AB31: =H33 -> 0.017 | AC31: =1000000*(O31*Q31*S31)^(1/3)/(I31+0.5*J31+240*K31) -> 4115.941
C32: M1no5 | D32: tb_zrnz | E32: 0.231 | F32: 0.124 | G32: 0.107 | H32: 0.015 | I32: 3784 | J32: 3453 | K32: 48 | L32: 4564 | M32: 5389 | N32: 67 | O32: 71 | P32: 65.5 | Q32: 66 | R32: 48 | S32: 73.5 | T32: 0 | U32: 2.037 | V32: 0.07 | W32: 4.02 | X32: =H29 -> 0.016 | Y32: =H30 -> 0.036 | Z32: =H31 -> 0.017 | AA32: =H32 -> 0.015 | AB32: =H33 -> 0.017 | AC32: =1000000*(O32*Q32*S32)^(1/3)/(I32+0.5*J32+240*K32) -> 4115.941 | AE32: ZR rate | AF32: 0 | AG32: 0.065 | AH32: 0.145 | AI32: 0.245 | AJ32: 0.36 | AK32: 0.395 | AL32: 0.645 | AM32: 0.815 | AN32: 0 | AO32: 0.065 | AP32: 0.145 | AQ32: 0.245 | AR32: 0.36 | AS32: 0.395 | AT32: 0.645 | AU32: 0.815 | AV32: 0 | AW32: 0.065 | AX32: 0.145 | AY32: 0.245 | AZ32: 0.36 | BA32: 0.395 | BB32: 0.645 | BC32: 0.815 | BD32: 0 | BE32: 0.065 | BF32: 0.145 | BG32: 0.245 | BH32: 0.36 | BI32: 0.395 | BJ32: 0.645 | BK32: 0.815 | BL32: 0 | BM32: 0.065 | BN32: 0.145 | BO32: 0.245 | BP32: 0.36 | BQ32: 0.395 | BR32: 0.645 | BS32: 0.815 | BT32: 0 | BU32: 0.065 | BV32: 0.145 | BW32: 0.245 | BX32: 0.36 | BY32: 0.395 | BZ32: 0.645 | CA32: 0.815 | CB32: 0 | CC32: 0.065 | CD32: 0.145 | CE32: 0.245 | CF32: 0.36 | CG32: 0.395 | CH32: 0.645 | CI32: 0.815 | CJ32: 0 | CK32: 0.065 | CL32: 0.145 | CM32: 0.245 | CN32: 0.36 | CO32: 0.395 | CP32: 0.645 | CQ32: 0.815
C33: M1no5 | D33: tb_zrzr | E33: 0.234 | F33: 0.127 | G33: 0.107 | H33: 0.017 | I33: 3784 | J33: 3453 | K33: 48 | L33: 4564 | M33: 5389 | N33: 67 | O33: 71 | P33: 65.5 | Q33: 66 | R33: 48 | S33: 73.5 | T33: =(N28*O28*P28*Q28*R28*S28)/(I28*J28*K28*(F28*H28 + F29*H29 + F30*H30 + F31*H31 + F32*H32 + F33*H33)) -> 5967.8049 | U33: 2.037 | V33: 0.07 | W33: 4.02 | X33: =H29 -> 0.016 | Y33: =H30 -> 0.036 | Z33: =H31 -> 0.017 | AA33: =H32 -> 0.015 | AB33: =H33 -> 0.017 | AC33: =1000000*(O33*Q33*S33)^(1/3)/(I33+0.5*J33+240*K33) -> 4115.941 | AE33: Score | AF33: =($O33*$Q33*$S33)^(1/3)/(AF28*((1-AF$2)*$H28+AF$2*$H29) + AF30*((1-AF$2)*$H30+AF$2*$H31) + AF32*((1-AF$2)*$H32+AF$2*$H33)) -> 1894.5009 | AG33: =($O33*$Q33*$S33)^(1/3)/(AG28*((1-AG$2)*$H28+AG$2*$H29) + AG30*((1-AG$2)*$H30+AG$2*$H31) + AG32*((1-AG$2)*$H32+AG$2*$H33)) -> 1977.3352 | AH33: =($O33*$Q33*$S33)^(1/3)/(AH28*((1-AH$2)*$H28+AH$2*$H29) + AH30*((1-AH$2)*$H30+AH$2*$H31) + AH32*((1-AH$2)*$H32+AH$2*$H33)) -> 2086.2064 | AI33: =($O33*$Q33*$S33)^(1/3)/(AI28*((1-AI$2)*$H28+AI$2*$H29) + AI30*((1-AI$2)*$H30+AI$2*$H31) + AI32*((1-AI$2)*$H32+AI$2*$H33)) -> 2535.1368 | AJ33: =($O33*$Q33*$S33)^(1/3)/(AJ28*((1-AJ$2)*$H28+AJ$2*$H29) + AJ30*((1-AJ$2)*$H30+AJ$2*$H31) + AJ32*((1-AJ$2)*$H32+AJ$2*$H33)) -> 2433.9074 | AK33: =($O33*$Q33*$S33)^(1/3)/(AK28*((1-AK$2)*$H28+AK$2*$H29) + AK30*((1-AK$2)*$H30+AK$2*$H31) + AK32*((1-AK$2)*$H32+AK$2*$H33)) -> 2878.7077 | AL33: =($O33*$Q33*$S33)^(1/3)/(AL28*((1-AL$2)*$H28+AL$2*$H29) + AL30*((1-AL$2)*$H30+AL$2*$H31) + AL32*((1-AL$2)*$H32+AL$2*$H33)) -> 3101.6165 | AM33: =($O33*$Q33*$S33)^(1/3)/(AM28*((1-AM$2)*$H28+AM$2*$H29) + AM30*((1-AM$2)*$H30+AM$2*$H31) + AM32*((1-AM$2)*$H32+AM$2*$H33)) -> 3699.0255 | ... CQ33: =($O33*$Q33*$S33)^(1/3)/(CQ28*((1-CQ$2)*$H28+CQ$2*$H29) + CQ30*((1-CQ$2)*$H30+CQ$2*$H31) + CQ32*((1-CQ$2)*$H32+CQ$2*$H33)) -> 4078.4921 | CS33: =100*$AF33/AF33 -> 100 | CT33: =100*$AF33/AG33 -> 95.810811 | CU33: =100*$AF33/AH33 -> 90.810811 | CV33: =100*$AF33/AI33 -> 74.72973 | CW33: =100*$AF33/AJ33 -> 77.837838 | CX33: =100*$AF33/AK33 -> 65.810811 | CY33: =100*$AF33/AL33 -> 61.081081 | CZ33: =100*$AF33/AM33 -> 51.216216 | ... FD33: =100*$AF33/CQ33 -> 46.451014
C34: M1no6 | D34: tb_nznz | E34: 0.261 | F34: 0.154 | G34: 0.108 | H34: 0.038 | I34: 3793 | J34: 3637 | K34: 48 | L34: 4579 | M34: 5573 | N34: 67 | O34: 71 | P34: 65.5 | Q34: 66 | R34: 48 | S34: 73.5 | T34: 0 | U34: 1.818 | V34: 0.068 | W34: 4.02 | X34: =H35 -> 0.016 | Y34: =H36 -> 0.037 | Z34: =H37 -> 0.017 | AA34: =H38 -> 0.015 | AB34: =H39 -> 0.017 | AC34: =1000000*(O34*Q34*S34)^(1/3)/(I34+0.5*J34+240*K34) -> 4091.6752 | AE34: NZ rate | AF34: 1 | AG34: 0.815 | AH34: 0.645 | AI34: 0.395 | AJ34: 0.36 | AK34: 0.245 | AL34: 0.145 | AM34: 0.065 | AN34: 1 | AO34: 0.815 | AP34: 0.645 | AQ34: 0.395 | AR34: 0.36 | AS34: 0.245 | AT34: 0.145 | AU34: 0.065 | AV34: 1 | AW34: 0.815 | AX34: 0.645 | AY34: 0.395 | AZ34: 0.36 | BA34: 0.245 | BB34: 0.145 | BC34: 0.065 | BD34: 1 | BE34: 0.815 | BF34: 0.645 | BG34: 0.395 | BH34: 0.36 | BI34: 0.245 | BJ34: 0.145 | BK34: 0.065 | BL34: 1 | BM34: 0.815 | BN34: 0.645 | BO34: 0.395 | BP34: 0.36 | BQ34: 0.245 | BR34: 0.145 | BS34: 0.065 | BT34: 1 | BU34: 0.815 | BV34: 0.645 | BW34: 0.395 | BX34: 0.36 | BY34: 0.245 | BZ34: 0.145 | CA34: 0.065 | CB34: 1 | CC34: 0.815 | CD34: 0.645 | CE34: 0.395 | CF34: 0.36 | CG34: 0.245 | CH34: 0.145 | CI34: 0.065 | CJ34: 1 | CK34: 0.815 | CL34: 0.645 | CM34: 0.395 | CN34: 0.36 | CO34: 0.245 | CP34: 0.145 | CQ34: 0.065
C35: M1no6 | D35: tb_nzzr | E35: 0.233 | F35: 0.126 | G35: 0.107 | H35: 0.016 | I35: 3793 | J35: 3637 | K35: 48 | L35: 4579 | M35: 5573 | N35: 67 | O35: 71 | P35: 65.5 | Q35: 66 | R35: 48 | S35: 73.5 | T35: 0 | U35: 1.818 | V35: 0.068 | W35: 4.02 | X35: =H35 -> 0.016 | Y35: =H36 -> 0.037 | Z35: =H37 -> 0.017 | AA35: =H38 -> 0.015 | AB35: =H39 -> 0.017 | AC35: =1000000*(O35*Q35*S35)^(1/3)/(I35+0.5*J35+240*K35) -> 4091.6752
C36: M1no6 | D36: tb_swnz | E36: 0.261 | F36: 0.153 | G36: 0.108 | H36: 0.037 | I36: 3793 | J36: 3637 | K36: 48 | L36: 4579 | M36: 5573 | N36: 67 | O36: 71 | P36: 65.5 | Q36: 66 | R36: 48 | S36: 73.5 | T36: 0 | U36: 1.818 | V36: 0.068 | W36: 4.02 | X36: =H35 -> 0.016 | Y36: =H36 -> 0.037 | Z36: =H37 -> 0.017 | AA36: =H38 -> 0.015 | AB36: =H39 -> 0.017 | AC36: =1000000*(O36*Q36*S36)^(1/3)/(I36+0.5*J36+240*K36) -> 4091.6752 | AE36: SW rate | AF36: 0 | AG36: 0.12 | AH36: 0.21 | AI36: 0.26 | AJ36: 0.28 | AK36: 0.26 | AL36: 0.21 | AM36: 0.12 | AN36: 0 | AO36: 0.12 | AP36: 0.21 | AQ36: 0.26 | AR36: 0.28 | AS36: 0.26 | AT36: 0.21 | AU36: 0.12 | AV36: 0 | AW36: 0.12 | AX36: 0.21 | AY36: 0.26 | AZ36: 0.28 | BA36: 0.26 | BB36: 0.21 | BC36: 0.12 | BD36: 0 | BE36: 0.12 | BF36: 0.21 | BG36: 0.26 | BH36: 0.28 | BI36: 0.26 | BJ36: 0.21 | BK36: 0.12 | BL36: 0 | BM36: 0.12 | BN36: 0.21 | BO36: 0.26 | BP36: 0.28 | BQ36: 0.26 | BR36: 0.21 | BS36: 0.12 | BT36: 0 | BU36: 0.12 | BV36: 0.21 | BW36: 0.26 | BX36: 0.28 | BY36: 0.26 | BZ36: 0.21 | CA36: 0.12 | CB36: 0 | CC36: 0.12 | CD36: 0.21 | CE36: 0.26 | CF36: 0.28 | CG36: 0.26 | CH36: 0.21 | CI36: 0.12 | CJ36: 0 | CK36: 0.12 | CL36: 0.21 | CM36: 0.26 | CN36: 0.28 | CO36: 0.26 | CP36: 0.21 | CQ36: 0.12
C37: M1no6 | D37: tb_swzr | E37: 0.234 | F37: 0.127 | G37: 0.107 | H37: 0.017 | I37: 3793 | J37: 3637 | K37: 48 | L37: 4579 | M37: 5573 | N37: 67 | O37: 71 | P37: 65.5 | Q37: 66 | R37: 48 | S37: 73.5 | T37: 0 | U37: 1.818 | V37: 0.068 | W37: 4.02 | X37: =H35 -> 0.016 | Y37: =H36 -> 0.037 | Z37: =H37 -> 0.017 | AA37: =H38 -> 0.015 | AB37: =H39 -> 0.017 | AC37: =1000000*(O37*Q37*S37)^(1/3)/(I37+0.5*J37+240*K37) -> 4091.6752
C38: M1no6 | D38: tb_zrnz | E38: 0.231 | F38: 0.124 | G38: 0.107 | H38: 0.015 | I38: 3793 | J38: 3637 | K38: 48 | L38: 4579 | M38: 5573 | N38: 67 | O38: 71 | P38: 65.5 | Q38: 66 | R38: 48 | S38: 73.5 | T38: 0 | U38: 1.818 | V38: 0.068 | W38: 4.02 | X38: =H35 -> 0.016 | Y38: =H36 -> 0.037 | Z38: =H37 -> 0.017 | AA38: =H38 -> 0.015 | AB38: =H39 -> 0.017 | AC38: =1000000*(O38*Q38*S38)^(1/3)/(I38+0.5*J38+240*K38) -> 4091.6752 | AE38: ZR rate | AF38: 0 | AG38: 0.065 | AH38: 0.145 | AI38: 0.245 | AJ38: 0.36 | AK38: 0.395 | AL38: 0.645 | AM38: 0.815 | AN38: 0 | AO38: 0.065 | AP38: 0.145 | AQ38: 0.245 | AR38: 0.36 | AS38: 0.395 | AT38: 0.645 | AU38: 0.815 | AV38: 0 | AW38: 0.065 | AX38: 0.145 | AY38: 0.245 | AZ38: 0.36 | BA38: 0.395 | BB38: 0.645 | BC38: 0.815 | BD38: 0 | BE38: 0.065 | BF38: 0.145 | BG38: 0.245 | BH38: 0.36 | BI38: 0.395 | BJ38: 0.645 | BK38: 0.815 | BL38: 0 | BM38: 0.065 | BN38: 0.145 | BO38: 0.245 | BP38: 0.36 | BQ38: 0.395 | BR38: 0.645 | BS38: 0.815 | BT38: 0 | BU38: 0.065 | BV38: 0.145 | BW38: 0.245 | BX38: 0.36 | BY38: 0.395 | BZ38: 0.645 | CA38: 0.815 | CB38: 0 | CC38: 0.065 | CD38: 0.145 | CE38: 0.245 | CF38: 0.36 | CG38: 0.395 | CH38: 0.645 | CI38: 0.815 | CJ38: 0 | CK38: 0.065 | CL38: 0.145 | CM38: 0.245 | CN38: 0.36 | CO38: 0.395 | CP38: 0.645 | CQ38: 0.815
C39: M1no6 | D39: tb_zrzr | E39: 0.234 | F39: 0.127 | G39: 0.107 | H39: 0.017 | I39: 3793 | J39: 3637 | K39: 48 | L39: 4579 | M39: 5573 | N39: 67 | O39: 71 | P39: 65.5 | Q39: 66 | R39: 48 | S39: 73.5 | T39: =(N34*O34*P34*Q34*R34*S34)/(I34*J34*K34*(F34*H34 + F35*H35 + F36*H36 + F37*H37 + F38*H38 + F39*H39)) -> 5559.7987 | U39: 1.818 | V39: 0.068 | W39: 4.02 | X39: =H35 -> 0.016 | Y39: =H36 -> 0.037 | Z39: =H37 -> 0.017 | AA39: =H38 -> 0.015 | AB39: =H39 -> 0.017 | AC39: =1000000*(O39*Q39*S39)^(1/3)/(I39+0.5*J39+240*K39) -> 4091.6752 | AE39: Score | AF39: =($O39*$Q39*$S39)^(1/3)/(AF34*((1-AF$2)*$H34+AF$2*$H35) + AF36*((1-AF$2)*$H36+AF$2*$H37) + AF38*((1-AF$2)*$H38+AF$2*$H39)) -> 1844.6456 | AG39: =($O39*$Q39*$S39)^(1/3)/(AG34*((1-AG$2)*$H34+AG$2*$H35) + AG36*((1-AG$2)*$H36+AG$2*$H37) + AG38*((1-AG$2)*$H38+AG$2*$H39)) -> 1926.5228 | AH39: =($O39*$Q39*$S39)^(1/3)/(AH34*((1-AH$2)*$H34+AH$2*$H35) + AH36*((1-AH$2)*$H36+AH$2*$H37) + AH38*((1-AH$2)*$H38+AH$2*$H39)) -> 2034.4372 | AI39: =($O39*$Q39*$S39)^(1/3)/(AI34*((1-AI$2)*$H34+AI$2*$H35) + AI36*((1-AI$2)*$H36+AI$2*$H37) + AI38*((1-AI$2)*$H38+AI$2*$H39)) -> 2476.4718 | AJ39: =($O39*$Q39*$S39)^(1/3)/(AJ34*((1-AJ$2)*$H34+AJ$2*$H35) + AJ36*((1-AJ$2)*$H36+AJ$2*$H37) + AJ38*((1-AJ$2)*$H38+AJ$2*$H39)) -> 2380.9964 | AK39: =($O39*$Q39*$S39)^(1/3)/(AK34*((1-AK$2)*$H34+AK$2*$H35) + AK36*((1-AK$2)*$H36+AK$2*$H37) + AK38*((1-AK$2)*$H38+AK$2*$H39)) -> 2820.2186 | AL39: =($O39*$Q39*$S39)^(1/3)/(AL34*((1-AL$2)*$H34+AL$2*$H35) + AL36*((1-AL$2)*$H36+AL$2*$H37) + AL38*((1-AL$2)*$H38+AL$2*$H39)) -> 3053.6499 | AM39: =($O39*$Q39*$S39)^(1/3)/(AM34*((1-AM$2)*$H34+AM$2*$H35) + AM36*((1-AM$2)*$H36+AM$2*$H37) + AM38*((1-AM$2)*$H38+AM$2*$H39)) -> 3663.2628 | ... CQ39: =($O39*$Q39*$S39)^(1/3)/(CQ34*((1-CQ$2)*$H34+CQ$2*$H35) + CQ36*((1-CQ$2)*$H36+CQ$2*$H37) + CQ38*((1-CQ$2)*$H38+CQ$2*$H39)) -> 4073.0118 | CS39: =100*$AF39/AF39 -> 100 | CT39: =100*$AF39/AG39 -> 95.75 | CU39: =100*$AF39/AH39 -> 90.671053 | CV39: =100*$AF39/AI39 -> 74.486842 | CW39: =100*$AF39/AJ39 -> 77.473684 | CX39: =100*$AF39/AK39 -> 65.407895 | CY39: =100*$AF39/AL39 -> 60.407895 | CZ39: =100*$AF39/AM39 -> 50.355263 | ... FD39: =100*$AF39/CQ39 -> 45.289474
C40: M1no7 | D40: tb_nznz | E40: 0.264 | F40: 0.156 | G40: 0.108 | H40: 0.039 | I40: 3825 | J40: 3573 | K40: 48 | L40: 4621 | M40: 5509 | N40: 67 | O40: 71 | P40: 65.5 | Q40: 66 | R40: 48 | S40: 73.5 | T40: 0 | U40: 1.822 | V40: 0.064 | W40: 4.02 | X40: =H41 -> 0.024 | Y40: =H42 -> 0.038 | Z40: =H43 -> 0.024 | AA40: =H44 -> 0.016 | AB40: =H45 -> 0.024 | AC40: =1000000*(O40*Q40*S40)^(1/3)/(I40+0.5*J40+240*K40) -> 4091.6752 | AE40: NZ rate | AF40: 1 | AG40: 0.815 | AH40: 0.645 | AI40: 0.395 | AJ40: 0.36 | AK40: 0.245 | AL40: 0.145 | AM40: 0.065 | AN40: 1 | AO40: 0.815 | AP40: 0.645 | AQ40: 0.395 | AR40: 0.36 | AS40: 0.245 | AT40: 0.145 | AU40: 0.065 | AV40: 1 | AW40: 0.815 | AX40: 0.645 | AY40: 0.395 | AZ40: 0.36 | BA40: 0.245 | BB40: 0.145 | BC40: 0.065 | BD40: 1 | BE40: 0.815 | BF40: 0.645 | BG40: 0.395 | BH40: 0.36 | BI40: 0.245 | BJ40: 0.145 | BK40: 0.065 | BL40: 1 | BM40: 0.815 | BN40: 0.645 | BO40: 0.395 | BP40: 0.36 | BQ40: 0.245 | BR40: 0.145 | BS40: 0.065 | BT40: 1 | BU40: 0.815 | BV40: 0.645 | BW40: 0.395 | BX40: 0.36 | BY40: 0.245 | BZ40: 0.145 | CA40: 0.065 | CB40: 1 | CC40: 0.815 | CD40: 0.645 | CE40: 0.395 | CF40: 0.36 | CG40: 0.245 | CH40: 0.145 | CI40: 0.065 | CJ40: 1 | CK40: 0.815 | CL40: 0.645 | CM40: 0.395 | CN40: 0.36 | CO40: 0.245 | CP40: 0.145 | CQ40: 0.065
...

Sheet dynamic vs fixed HW util.
C2: ConverterOverhead | F2: Detector Overhead
C3: Engine | D3: LUT | E3: FF | F3: LUT | G3: FF
C4: M5 | D4: 18 | E4: 8 | F4: 8 | G4: 0
C5: M4 | D5: 23 | E5: 8 | F5: 8 | G5: 0
C6: M3 | D6: 20 | E6: 7 | F6: 8 | G6: 0
C7: M2 | D7: 19 | E7: 6 | F7: 8 | G7: 0
C8: M1 | D8: 12 | E8: 5 | F8: 8 | G8: 0
C11: PE | I11: PE
C12: Engine | D12: LUT | E12: FF | F12: BRAM36k | G12: AREA | H12: Exclude BRAM | I12: Engine | J12: LUT | K12: FF | L12: BRAM36k
C13: M5no1 | D13: 82 | E13: 72 | F13: 72 | G13: =64*(D13+0.5*E13)+240*F13 -> 24832 | H13: =D13+0.5*E13 -> 118 | I13: Default | J13: 100 | K13: 74 | L13: 72
C14: M5no2 | D14: 92 | E14: 73 | F14: 72 | G14: =64*(D14+0.5*E14)+240*F14 -> 25504 | H14: =D14+0.5*E14 -> 128.5 | I14: Fixed7 | J14: 93 | K14: 73 | L14: 72
C15: M5no3 | D15: 92 | E15: 75 | F15: 72 | G15: =64*(D15+0.5*E15)+240*F15 -> 25568 | H15: =D15+0.5*E15 -> 129.5 | I15: Fixed6 | J15: 74 | K15: 68 | L15: 64
C16: M5no4 | D16: 92 | E16: 73 | F16: 72 | G16: =64*(D16+0.5*E16)+240*F16 -> 25504 | H16: =D16+0.5*E16 -> 128.5 | I16: Fixed5 | J16: 51 | K16: 63 | L16: 56
C17: M5no5 | D17: 97 | E17: 73 | F17: 72 | G17: =64*(D17+0.5*E17)+240*F17 -> 25824 | H17: =D17+0.5*E17 -> 133.5 | I17: Fixed4 | J17: 44 | K17: 58 | L17: 48
C18: M5no6 | D18: 93 | E18: 75 | F18: 72 | G18: =64*(D18+0.5*E18)+240*F18 -> 25632 | H18: =D18+0.5*E18 -> 130.5
C19: M5no7 | D19: 92 | E19: 74 | F19: 72 | G19: =64*(D19+0.5*E19)+240*F19 -> 25536 | H19: =D19+0.5*E19 -> 129
C20: M5no8 | D20: 93 | E20: 74 | F20: 72 | G20: =64*(D20+0.5*E20)+240*F20 -> 25600 | H20: =D20+0.5*E20 -> 130
C21: M5no9 | D21: 92 | E21: 76 | F21: 72 | G21: =64*(D21+0.5*E21)+240*F21 -> 25600 | H21: =D21+0.5*E21 -> 130
C22: M4no1 | D22: 89 | E22: 71 | F22: 72 | G22: =64*(D22+0.5*E22)+240*F22 -> 25248 | H22: =D22+0.5*E22 -> 124.5
C23: M4no2 | D23: 85 | E23: 72 | F23: 72 | G23: =64*(D23+0.5*E23)+240*F23 -> 25024 | H23: =D23+0.5*E23 -> 121
C24: M4no3 | D24: 86 | E24: 74 | F24: 72 | G24: =64*(D24+0.5*E24)+240*F24 -> 25152 | H24: =D24+0.5*E24 -> 123
C25: M4no4 | D25: 85 | E25: 72 | F25: 72 | G25: =64*(D25+0.5*E25)+240*F25 -> 25024 | H25: =D25+0.5*E25 -> 121
C26: M4no5 | D26: 86 | E26: 72 | F26: 72 | G26: =64*(D26+0.5*E26)+240*F26 -> 25088 | H26: =D26+0.5*E26 -> 122
C27: M4no6 | D27: 85 | E27: 74 | F27: 72 | G27: =64*(D27+0.5*E27)+240*F27 -> 25088 | H27: =D27+0.5*E27 -> 122
C28: M4no7 | D28: 86 | E28: 73 | F28: 72 | G28: =64*(D28+0.5*E28)+240*F28 -> 25120 | H28: =D28+0.5*E28 -> 122.5
C29: M4no8 | D29: 85 | E29: 73 | F29: 72 | G29: =64*(D29+0.5*E29)+240*F29 -> 25056 | H29: =D29+0.5*E29 -> 121.5
... C57: M1no9 | D57: 59 | E57: 59 | F57: 48 | G57: =64*(D57+0.5*E57)+240*F57 -> 17184 | H57: =D57+0.5*E57 -> 88.5

Sheet energy consumption
Q6: M1no1 | R6: Input | S6: 0 | T6: 0.125 | U6: 0.25 | V6: 0.375 | W6: 0.5 | X6: 0.625 | Y6: 0.75 | Z6: 0.875
Q7: Weight | R7: 0 | S7: ='dynamic scaling metrics'!CS9 -> 100 | T7: ='dynamic scaling metrics'!CT9 -> 99.394737 | U7: ='dynamic scaling metrics'!CU9 -> 97.131579 | V7: ='dynamic scaling metrics'!CV9 -> 82.657895 | W7: ='dynamic scaling metrics'!CW9 -> 86.526316 | X7: ='dynamic scaling metrics'!CX9 -> 73.973684 | Y7: ='dynamic scaling metrics'!CY9 -> 68.184211 | Z7: ='dynamic scaling metrics'!CZ9 -> 55.973684
R8: 0.125 | S8: ='dynamic scaling metrics'!DA9 -> 94.407895 | T8: ='dynamic scaling metrics'!DB9 -> 94.243421 | U8: ='dynamic scaling metrics'!DC9 -> 92.598684 | V8: ='dynamic scaling metrics'!DD9 -> 79.539474 | W8: ='dynamic scaling metrics'!DE9 -> 83.881579 | X8: ='dynamic scaling metrics'!DF9 -> 72.236842 | Y8: ='dynamic scaling metrics'!DG9 -> 68.256579 | Z8: ='dynamic scaling metrics'!DH9 -> 57.730263
R9: 0.25 | S9: ='dynamic scaling metrics'!DI9 -> 88.815789 | T9: ='dynamic scaling metrics'!DJ9 -> 89.092105 | U9: ='dynamic scaling metrics'!DK9 -> 88.065789 | V9: ='dynamic scaling metrics'!DL9 -> 76.421053 | W9: ='dynamic scaling metrics'!DM9 -> 81.236842 | X9: ='dynamic scaling metrics'!DN9 -> 70.5 | Y9: ='dynamic scaling metrics'!DO9 -> 68.328947 | Z9: ='dynamic scaling metrics'!DP9 -> 59.486842
R10: 0.375 | S10: ='dynamic scaling metrics'!DQ9 -> 83.223684 | T10: ='dynamic scaling metrics'!DR9 -> 83.940789 | U10: ='dynamic scaling metrics'!DS9 -> 83.532895 | V10: ='dynamic scaling metrics'!DT9 -> 73.302632 | W10: ='dynamic scaling metrics'!DU9 -> 78.592105 | X10: ='dynamic scaling metrics'!DV9 -> 68.763158 | Y10: ='dynamic scaling metrics'!DW9 -> 68.401316 | Z10: ='dynamic scaling metrics'!DX9 -> 61.243421 | AK10: Name of Engine | AL10: Average of Energy consumption of the mainstream AI area (the green cells) normalized by Fully compact environment
R11: 0.5 | S11: ='dynamic scaling metrics'!DX9 -> 61.243421 | T11: ='dynamic scaling metrics'!DY9 -> 77.631579 | U11: ='dynamic scaling metrics'!DZ9 -> 78.789474 | V11: ='dynamic scaling metrics'!EA9 -> 79 | W11: ='dynamic scaling metrics'!EB9 -> 70.184211 | X11: ='dynamic scaling metrics'!EC9 -> 75.947368 | Y11: ='dynamic scaling metrics'!ED9 -> 67.026316 | Z11: ='dynamic scaling metrics'!EE9 -> 68.473684 | AK11: =Q6 -> M1no1
R12: 0.625 | S12: ='dynamic scaling metrics'!EF9 -> 63 | T12: ='dynamic scaling metrics'!EG9 -> 72.039474 | U12: ='dynamic scaling metrics'!EH9 -> 73.638158 | V12: ='dynamic scaling metrics'!EI9 -> 74.467105 | W12: ='dynamic scaling metrics'!EJ9 -> 67.065789 | X12: ='dynamic scaling metrics'!EK9 -> 73.302632 | Y12: ='dynamic scaling metrics'!EL9 -> 65.289474 | Z12: ='dynamic scaling metrics'!EM9 -> 68.546053 | AB12: 0 | AC12: 0.125 | AD12: 0.25 | AE12: 0.375 | AF12: 0.5 | AG12: 0.625 | AH12: 0.75 | AI12: 0.875 | AK12: MainStream AI | AL12: =AVERAGE(U11:X12,AD13:AG13) -> 72.118421
Q13: M1no2 | R13: 0 | S13: ='dynamic scaling metrics'!CS15 -> 100 | T13: ='dynamic scaling metrics'!CT15 -> 99.269231 | U13: ='dynamic scaling metrics'!CU15 -> 97.038462 | V13: ='dynamic scaling metrics'!CV15 -> 82.807692 | W13: ='dynamic scaling metrics'!CW15 -> 87.076923 | X13: ='dynamic scaling metrics'!CX15 -> 74.730769 | Y13: ='dynamic scaling metrics'!CY15 -> 70.115385 | Z13: ='dynamic scaling metrics'!CZ15 -> 58.884615 | AA13: 0.75 | AB13: ='dynamic scaling metrics'!EN9 -> 64.756579 | AC13: ='dynamic scaling metrics'!EO9 -> 66.447368 | AD13: ='dynamic scaling metrics'!EP9 -> 68.486842 | AE13: ='dynamic scaling metrics'!EQ9 -> 69.934211 | AF13: ='dynamic scaling metrics'!ER9 -> 63.947368 | AG13: ='dynamic scaling metrics'!ES9 -> 70.657895 | AH13: ='dynamic scaling metrics'!ET9 -> 63.552632 | AI13: ='dynamic scaling metrics'!EU9 -> 68.618421
Q14: Weight | R14: 0.125 | S14: ='dynamic scaling metrics'!DA15 -> 92.948718 | T14: ='dynamic scaling metrics'!DB15 -> 92.36859 | U14: ='dynamic scaling metrics'!DC15 -> 90.471154 | V14: ='dynamic scaling metrics'!DD15 -> 77.522436 | W14: ='dynamic scaling metrics'!DE15 -> 81.846154 | X14: ='dynamic scaling metrics'!DF15 -> 70.503205 | Y14: ='dynamic scaling metrics'!DG15 -> 67.073718 | Z14: ='dynamic scaling metrics'!DH15 -> 57.272436 | AA14: 0.875 | AB14: ='dynamic scaling metrics'!EV9 -> 66.513158 | AC14: ='dynamic scaling metrics'!EW9 -> 60.855263 | AD14: ='dynamic scaling metrics'!EX9 -> 63.335526 | AE14: ='dynamic scaling metrics'!EY9 -> 65.401316 | AF14: ='dynamic scaling metrics'!EZ9 -> 60.828947 | AG14: ='dynamic scaling metrics'!FA9 -> 68.013158 | AH14: ='dynamic scaling metrics'!FB9 -> 61.815789 | AI14: ='dynamic scaling metrics'!FC9 -> 68.690789
R15: 0.25 | S15: ='dynamic scaling metrics'!DI15 -> 85.897436 | T15: ='dynamic scaling metrics'!DJ15 -> 85.467949 | U15: ='dynamic scaling metrics'!DK15 -> 83.903846 | V15: ='dynamic scaling metrics'!DL15 -> 72.237179 | W15: ='dynamic scaling metrics'!DM15 -> 76.615385 | X15: ='dynamic scaling metrics'!DN15 -> 66.275641 | Y15: ='dynamic scaling metrics'!DO15 -> 64.032051 | Z15: ='dynamic scaling metrics'!DP15 -> 55.660256
